Workbook
Name ____ELE1: #REF!
Name ____EPE1: #REF!
Name ____VTL04: #REF!
Name ___CAF4: #REF!
Name ___ELE1: #REF!
Name ___EPE1: #REF!
Name ___PV42: #REF!
Name ___PV44: #REF!
Name ___SKY1: #REF!
Name ___SKY2: #REF!
Name ___VTL01: #REF!
Name ___VTL02: #REF!
Name ___VTL03: #REF!
Name ___VTL05: #REF!
Name ___VTL06: #REF!
Name ___VTL07: #REF!
Name ___VTL08: #REF!
Name ___VTL09: #REF!
Name __CAF4: #REF!
Name __ELE1: #REF!
Name __ELE1: #REF!
Name __EPE1: #REF!
Name __EPE1: #REF!
Name __PV42: #REF!
Name __PV44: #REF!
Name __SKY1: #REF!
Name __SKY2: #REF!
Name __VTL01: #REF!
Name __VTL02: #REF!
Name __VTL03: #REF!
Name __VTL04: #REF!
Name __VTL05: #REF!
Name __VTL06: #REF!
Name __VTL07: #REF!
Name __VTL08: #REF!
Name __VTL09: #REF!
Name _1Excel_BuiltIn_Print_Area_4_1_1: #REF!
Name _C: #REF!
Name _CAF4: '[9]Base de Dados'!$H$33
Name _D: #REF!
Name _ELE1: #REF!
Name _ELE1: #REF!
Name _EPE1: #REF!
Name _EPE1: #REF!
Name _P: #REF!
Name _PV42: '[9]Base de Dados'!$H$29
Name _PV44: '[9]Base de Dados'!$H$30
Name _SKY1: '[9]Base de Dados'!$H$36
Name _SKY2: '[9]Base de Dados'!$H$35
Name _VTL01: [9]Plan1!$Y$8
Name _VTL02: [9]Plan1!$Y$13
Name _VTL03: [9]Plan1!$Y$21
Name _VTL04: [12]VT!#REF!
Name _VTL04: [12]VT!#REF!
Name _VTL05: [9]Plan1!$Y$26
Name _VTL06: [9]Plan1!$Y$31
Name _VTL07: [9]Plan1!$Y$35
Name _VTL08: [9]Plan1!$Y$38
Name _VTL09: [9]Plan1!$Y$41
Name A: #REF!

Sheet AEO
L2: Nº SI / Nº AEO
F3: AUTORIZAÇÃO DE EXECUÇÃO DE OBRAS - AEO | L3: 03396-26
B7: AUTOMAÇÃO
B9: DISTRIBUIDORA
B10: EQUATORIAL GOIÁS
B12: Contrato: | C12: Linha: | D12: Empreiteira: | H12: Valor Original: | J12: Valor Adicional: | L12: Valor Total Autorizado:
B13: 4600027637 | C13: =VLOOKUP(B13,Contratos!E:H,4,0) -> 10 | D13: =VLOOKUP(B13,Contratos!E:G,3,0) -> ENERGY SYSTEN CONSTRUCOES E MANUTEN | H13: =SUMPRODUCT('Lista de Serviços & Medição'!F:F,'Lista de Serviços & Medição'!H:H) -> 56770.435 | J13: =SUMPRODUCT('Lista de Serviços & Medição'!G:G,'Lista de Serviços & Medição'!H:H) -> 0 | L13: =H13+J13 -> 56770.435
B15: IDENTIFICAÇÃO DO PROJETO: | G15: SUBESTAÇÃO: | J15: PEP / ORDEM:
B16: =VLOOKUP(J16,CN43N!C:D,2,0) -> EQTL-GO>SE BJE>69KV>AMP POTENCIA | G16: =VLOOKUP(J16,Portifólio!F:I,4,0) -> SE BOM JARDIM | J16: GO-2530208AMP0.F
B18: ESCOPO MACRO DA OBRA:
B20: =VLOOKUP(J16,Portifólio!F:J,5,0) -> 1,00 x SUBST. DE TRANSFORMADOR DE FORÇA + 1,00 x TRANSFORMADOR DE FORÇA 34,5/13,8kV 5,0/6,3MVA - YNYN0D1 + 1,00 x BARRAMENTO DUPLO OU BPT 13,8kV + 1,00 x ENTRADA DE LINHA 13,8kV c/ DJ
B26: AUTORIZAMOS EXECUTAR OS SERVIÇOS CONSTANTES NESTA AUTORIZAÇÃO, DENTRO DAS NORMAS BEM COMO DE ACORDO COM AS DEMAIS CONDIÇÕES ESTABELECIDAS NO CONTRATO DE EMPREITADAS EM VIGOR E RECOMENDAÇÕES EM ANEXO AO CONTRATO
B28: Prazo de Execução
B29: Início Autorizado: | C29: 46134 | G29: Liberação comissionamento esperado: | H29: 46135 | K29: Término Autorizado: | L29: 46137
B34: GUSTAVO DE JESUS OLIVEIRA | I34: =VLOOKUP(B13,Contratos!E:L,8,0) -> GIOVANNI CENDES FINOTTI
B35: =VLOOKUP(B34,Contratos!J:K,2,0) -> G52901707 | I35: =VLOOKUP(I34,Contratos!L:M,2,0) -> 027.157.771-16
B36: RESPONSÁVEL EQUATORIAL | I36: =D13 -> ENERGY SYSTEN CONSTRUCOES E MANUTEN

Sheet Lista de Serviços & Medição
E3: LISTA DE SERVIÇOS E PLANILHA DE MEDIÇÃO | I3: MEDIÇÃO | J3: Medição nº 01 | L3: Medição nº 02 | N3: Medição nº 03 | P3: Medição nº 04 | R3: Medição nº 05 | T3: Medição nº 06 | V3: Medição nº 07 | X3: Medição nº 08 | Z3: Medição nº 09 | AB3: Medição nº 10 | AD3: Medição nº 11 | AF3: Medição nº 12 | AH3: Medição nº 13 | AJ3: Medição nº 14 | AL3: Medição nº 15 | AN3: Medição nº 16 | AP3: Medição nº 17 | AR3: Medição nº 18 | AT3: Medição nº 19 | AV3: Medição nº 20
I4: Mês
I5: RC ODI
I6: RC CIV
I7: RC ODD
J8: VALORES DESTA MEDIÇÃO | L8: VALORES DESTA MEDIÇÃO | N8: VALORES DESTA MEDIÇÃO | P8: VALORES DESTA MEDIÇÃO | R8: VALORES DESTA MEDIÇÃO | T8: VALORES DESTA MEDIÇÃO | V8: VALORES DESTA MEDIÇÃO | X8: VALORES DESTA MEDIÇÃO | Z8: VALORES DESTA MEDIÇÃO | AB8: VALORES DESTA MEDIÇÃO | AD8: VALORES DESTA MEDIÇÃO | AF8: VALORES DESTA MEDIÇÃO | AH8: VALORES DESTA MEDIÇÃO | AJ8: VALORES DESTA MEDIÇÃO | AL8: VALORES DESTA MEDIÇÃO | AN8: VALORES DESTA MEDIÇÃO | AP8: VALORES DESTA MEDIÇÃO | AR8: VALORES DESTA MEDIÇÃO | AT8: VALORES DESTA MEDIÇÃO | AV8: VALORES DESTA MEDIÇÃO | AX8: TOTAIS ACUMULADOS | AZ8: SALDO A FATURAR | BA8: SALDO A FATURAR
B9: CÓDIGO SAP | C9: LINHA | D9: DESCRIMINAÇÃO DOS SERVICOS | E9: UNID. | F9: QUANT. PREVISTA ORIGINAL | G9: QUANT. ADICIONAL | H9: PREÇO UNITÁRIO | I9: R$ TOTAL
J11: QUANT. | K11: VALOR | L11: QUANT. | M11: VALOR | N11: QUANT. | O11: VALOR | P11: QUANT. | Q11: VALOR | R11: QUANT. | S11: VALOR | T11: QUANT. | U11: VALOR | V11: QUANT. | W11: VALOR | X11: QUANT. | Y11: VALOR | Z11: QUANT. | AA11: VALOR | AB11: QUANT. | AC11: VALOR | AD11: QUANT. | AE11: VALOR | AF11: QUANT. | AG11: VALOR | AH11: QUANT. | AI11: VALOR | AJ11: QUANT. | AK11: VALOR | AL11: QUANT. | AM11: VALOR | AN11: QUANT. | AO11: VALOR | AP11: QUANT. | AQ11: VALOR | AR11: QUANT. | AS11: VALOR | AT11: QUANT. | AU11: VALOR | AV11: QUANT. | AW11: VALOR | AX11: QUANT. | AY11: TOTAL | AZ11: QUANT. | BA11: TOTAL
D12: SERVIÇOS PRELIMINARES - MOBILIZAÇÃO & DESMOBILIZAÇÃO (FATOR "M") | I12: =SUBTOTAL(9,I13:I968) -> 56770.435 | K12: =SUBTOTAL(9,K13:K86) -> 14637.285 | M12: =SUBTOTAL(9,M13:M86) -> 0 | O12: =SUBTOTAL(9,O13:O86) -> 0 | Q12: =SUBTOTAL(9,Q13:Q86) -> 0 | S12: =SUBTOTAL(9,S13:S86) -> 0 | U12: =SUBTOTAL(9,U13:U86) -> 0 | W12: =SUBTOTAL(9,W13:W86) -> 0 | Y12: =SUBTOTAL(9,Y13:Y86) -> 0 | AA12: =SUBTOTAL(9,AA13:AA86) -> 0 | AC12: =SUBTOTAL(9,AC13:AC86) -> 0 | AE12: =SUBTOTAL(9,AE13:AE86) -> 0 | AG12: =SUBTOTAL(9,AG13:AG86) -> 0 | AI12: =SUBTOTAL(9,AI13:AI86) -> 0 | AK12: =SUBTOTAL(9,AK13:AK86) -> 0 | AM12: =SUBTOTAL(9,AM13:AM86) -> 0 | AO12: =SUBTOTAL(9,AO13:AO86) -> 0 | AQ12: =SUBTOTAL(9,AQ13:AQ86) -> 0 | AS12: =SUBTOTAL(9,AS13:AS86) -> 0 | AU12: =SUBTOTAL(9,AU13:AU86) -> 0 | AW12: =SUBTOTAL(9,AW13:AW86) -> 0 | AY12: =SUBTOTAL(9,AY13:AY86) -> 14637.285 | BA12: =SUBTOTAL(9,BA13:BA86) -> 2452.74
B13: 5045500013 | C13: =IFERROR(IF(B13,VLOOKUP((AEO!$B$13&AEO!$C$13&B13&E13),MSRV5!A:F,6,0),""),"N/A") -> 290 | D13: MOB / DESMOBILIZACAO LD DE 0 A 50KM LD | E13: =IF(B13,VLOOKUP(B13,MSRV5!B:D,3,0),"") -> KM | H13: =IFERROR(IF(B13,VLOOKUP((AEO!$B$13&AEO!$C$13&B13&E13),MSRV5!A:E,5,0),""),0) -> 589.16 | I13: =(F13+G13)*H13 -> 0 | K13: =J13*$H13 -> 0 | M13: =L13*$H13 -> 0 | O13: =N13*$H13 -> 0 | Q13: =P13*$H13 -> 0 | S13: =R13*$H13 -> 0 | U13: =T13*$H13 -> 0 | W13: =V13*$H13 -> 0 | Y13: =X13*$H13 -> 0 | AA13: =Z13*$H13 -> 0 | AC13: =AB13*$H13 -> 0 | AE13: =AD13*$H13 -> 0 | AG13: =AF13*$H13 -> 0 | AI13: =AH13*$H13 -> 0 | AK13: =AJ13*$H13 -> 0 | AM13: =AL13*$H13 -> 0 | AO13: =AN13*$H13 -> 0 | AQ13: =AP13*$H13 -> 0 | AS13: =AR13*$H13 -> 0 | AU13: =AT13*$H13 -> 0 | AW13: =AV13*$H13 -> 0 | AX13: =SUM(AV13,AT13,AR13,AP13,AN13,AL13,AJ13,AH13,AF13,AD13,AB13,Z13,X13,V13,T13,R13,P13,N13,L13,J13) -> 0 | AY13: =SUM(AW13,AU13,AS13,AQ13,AO13,AM13,AK13,AI13,AG13,AE13,AC13,AA13,Y13,W13,U13,S13,Q13,O13,M13,K13) -> 0 | AZ13: =(F13+G13)-AX13 -> 0 | BA13: =I13-AY13 -> 0
B14: 5045500014 | C14: =IFERROR(IF(B14,VLOOKUP((AEO!$B$13&AEO!$C$13&B14&E14),MSRV5!A:F,6,0),""),"N/A") -> 300 | D14: MOB / DESMOBILIZACAO LD DE 51 A 200KM LD | E14: =IF(B14,VLOOKUP(B14,MSRV5!B:D,3,0),"") -> KM | H14: =IFERROR(IF(B14,VLOOKUP((AEO!$B$13&AEO!$C$13&B14&E14),MSRV5!A:E,5,0),""),0) -> 643.72 | I14: =(F14+G14)*H14 -> 0 | K14: =J14*$H14 -> 0 | M14: =L14*$H14 -> 0 | O14: =N14*$H14 -> 0 | Q14: =P14*$H14 -> 0 | S14: =R14*$H14 -> 0 | U14: =T14*$H14 -> 0 | W14: =V14*$H14 -> 0 | Y14: =X14*$H14 -> 0 | AA14: =Z14*$H14 -> 0 | AC14: =AB14*$H14 -> 0 | AE14: =AD14*$H14 -> 0 | AG14: =AF14*$H14 -> 0 | AI14: =AH14*$H14 -> 0 | AK14: =AJ14*$H14 -> 0 | AM14: =AL14*$H14 -> 0 | AO14: =AN14*$H14 -> 0 | AQ14: =AP14*$H14 -> 0 | AS14: =AR14*$H14 -> 0 | AU14: =AT14*$H14 -> 0 | AW14: =AV14*$H14 -> 0 | AX14: =SUM(AV14,AT14,AR14,AP14,AN14,AL14,AJ14,AH14,AF14,AD14,AB14,Z14,X14,V14,T14,R14,P14,N14,L14,J14) -> 0 | AY14: =SUM(AW14,AU14,AS14,AQ14,AO14,AM14,AK14,AI14,AG14,AE14,AC14,AA14,Y14,W14,U14,S14,Q14,O14,M14,K14) -> 0 | AZ14: =(F14+G14)-AX14 -> 0 | BA14: =I14-AY14 -> 0
B15: 5045500015 | C15: =IFERROR(IF(B15,VLOOKUP((AEO!$B$13&AEO!$C$13&B15&E15),MSRV5!A:F,6,0),""),"N/A") -> 320 | D15: MOB/ DESMOBILIZACAO LD ACIMA DE 600KM LD | E15: =IF(B15,VLOOKUP(B15,MSRV5!B:D,3,0),"") -> KM | H15: =IFERROR(IF(B15,VLOOKUP((AEO!$B$13&AEO!$C$13&B15&E15),MSRV5!A:E,5,0),""),0) -> 207.38 | I15: =(F15+G15)*H15 -> 0 | K15: =J15*$H15 -> 0 | M15: =L15*$H15 -> 0 | O15: =N15*$H15 -> 0 | Q15: =P15*$H15 -> 0 | S15: =R15*$H15 -> 0 | U15: =T15*$H15 -> 0 | W15: =V15*$H15 -> 0 | Y15: =X15*$H15 -> 0 | AA15: =Z15*$H15 -> 0 | AC15: =AB15*$H15 -> 0 | AE15: =AD15*$H15 -> 0 | AG15: =AF15*$H15 -> 0 | AI15: =AH15*$H15 -> 0 | AK15: =AJ15*$H15 -> 0 | AM15: =AL15*$H15 -> 0 | AO15: =AN15*$H15 -> 0 | AQ15: =AP15*$H15 -> 0 | AS15: =AR15*$H15 -> 0 | AU15: =AT15*$H15 -> 0 | AW15: =AV15*$H15 -> 0 | AX15: =SUM(AV15,AT15,AR15,AP15,AN15,AL15,AJ15,AH15,AF15,AD15,AB15,Z15,X15,V15,T15,R15,P15,N15,L15,J15) -> 0 | AY15: =SUM(AW15,AU15,AS15,AQ15,AO15,AM15,AK15,AI15,AG15,AE15,AC15,AA15,Y15,W15,U15,S15,Q15,O15,M15,K15) -> 0 | AZ15: =(F15+G15)-AX15 -> 0 | BA15: =I15-AY15 -> 0
B16: 5045500016 | C16: =IFERROR(IF(B16,VLOOKUP((AEO!$B$13&AEO!$C$13&B16&E16),MSRV5!A:F,6,0),""),"N/A") -> 340 | D16: MOB/ DESMOBILIZACAO LD DE 201 A 400KM LD | E16: =IF(B16,VLOOKUP(B16,MSRV5!B:D,3,0),"") -> KM | H16: =IFERROR(IF(B16,VLOOKUP((AEO!$B$13&AEO!$C$13&B16&E16),MSRV5!A:E,5,0),""),0) -> 367.63 | I16: =(F16+G16)*H16 -> 0 | K16: =J16*$H16 -> 0 | M16: =L16*$H16 -> 0 | O16: =N16*$H16 -> 0 | Q16: =P16*$H16 -> 0 | S16: =R16*$H16 -> 0 | U16: =T16*$H16 -> 0 | W16: =V16*$H16 -> 0 | Y16: =X16*$H16 -> 0 | AA16: =Z16*$H16 -> 0 | AC16: =AB16*$H16 -> 0 | AE16: =AD16*$H16 -> 0 | AG16: =AF16*$H16 -> 0 | AI16: =AH16*$H16 -> 0 | AK16: =AJ16*$H16 -> 0 | AM16: =AL16*$H16 -> 0 | AO16: =AN16*$H16 -> 0 | AQ16: =AP16*$H16 -> 0 | AS16: =AR16*$H16 -> 0 | AU16: =AT16*$H16 -> 0 | AW16: =AV16*$H16 -> 0 | AX16: =SUM(AV16,AT16,AR16,AP16,AN16,AL16,AJ16,AH16,AF16,AD16,AB16,Z16,X16,V16,T16,R16,P16,N16,L16,J16) -> 0 | AY16: =SUM(AW16,AU16,AS16,AQ16,AO16,AM16,AK16,AI16,AG16,AE16,AC16,AA16,Y16,W16,U16,S16,Q16,O16,M16,K16) -> 0 | AZ16: =(F16+G16)-AX16 -> 0 | BA16: =I16-AY16 -> 0
B17: 5045500019 | C17: =IFERROR(IF(B17,VLOOKUP((AEO!$B$13&AEO!$C$13&B17&E17),MSRV5!A:F,6,0),""),"N/A") -> 350 | D17: DESMOBIL 0 A 200KM EQP 5H RESIT OHM LD | E17: =IF(B17,VLOOKUP(B17,MSRV5!B:D,3,0),"") -> CDA | H17: =IFERROR(IF(B17,VLOOKUP((AEO!$B$13&AEO!$C$13&B17&E17),MSRV5!A:E,5,0),""),0) -> 129.61 | I17: =(F17+G17)*H17 -> 0 | K17: =J17*$H17 -> 0 | M17: =L17*$H17 -> 0 | O17: =N17*$H17 -> 0 | Q17: =P17*$H17 -> 0 | S17: =R17*$H17 -> 0 | U17: =T17*$H17 -> 0 | W17: =V17*$H17 -> 0 | Y17: =X17*$H17 -> 0 | AA17: =Z17*$H17 -> 0 | AC17: =AB17*$H17 -> 0 | AE17: =AD17*$H17 -> 0 | AG17: =AF17*$H17 -> 0 | AI17: =AH17*$H17 -> 0 | AK17: =AJ17*$H17 -> 0 | AM17: =AL17*$H17 -> 0 | AO17: =AN17*$H17 -> 0 | AQ17: =AP17*$H17 -> 0 | AS17: =AR17*$H17 -> 0 | AU17: =AT17*$H17 -> 0 | AW17: =AV17*$H17 -> 0 | AX17: =SUM(AV17,AT17,AR17,AP17,AN17,AL17,AJ17,AH17,AF17,AD17,AB17,Z17,X17,V17,T17,R17,P17,N17,L17,J17) -> 0 | AY17: =SUM(AW17,AU17,AS17,AQ17,AO17,AM17,AK17,AI17,AG17,AE17,AC17,AA17,Y17,W17,U17,S17,Q17,O17,M17,K17) -> 0 | AZ17: =(F17+G17)-AX17 -> 0 | BA17: =I17-AY17 -> 0
B18: 5045500020 | C18: =IFERROR(IF(B18,VLOOKUP((AEO!$B$13&AEO!$C$13&B18&E18),MSRV5!A:F,6,0),""),"N/A") -> 360 | D18: DESMOBIL 0 A 200KM EQP 5H SERV TEC LD | E18: =IF(B18,VLOOKUP(B18,MSRV5!B:D,3,0),"") -> CDA | H18: =IFERROR(IF(B18,VLOOKUP((AEO!$B$13&AEO!$C$13&B18&E18),MSRV5!A:E,5,0),""),0) -> 164.96 | I18: =(F18+G18)*H18 -> 0 | K18: =J18*$H18 -> 0 | M18: =L18*$H18 -> 0 | O18: =N18*$H18 -> 0 | Q18: =P18*$H18 -> 0 | S18: =R18*$H18 -> 0 | U18: =T18*$H18 -> 0 | W18: =V18*$H18 -> 0 | Y18: =X18*$H18 -> 0 | AA18: =Z18*$H18 -> 0 | AC18: =AB18*$H18 -> 0 | AE18: =AD18*$H18 -> 0 | AG18: =AF18*$H18 -> 0 | AI18: =AH18*$H18 -> 0 | AK18: =AJ18*$H18 -> 0 | AM18: =AL18*$H18 -> 0 | AO18: =AN18*$H18 -> 0 | AQ18: =AP18*$H18 -> 0 | AS18: =AR18*$H18 -> 0 | AU18: =AT18*$H18 -> 0 | AW18: =AV18*$H18 -> 0 | AX18: =SUM(AV18,AT18,AR18,AP18,AN18,AL18,AJ18,AH18,AF18,AD18,AB18,Z18,X18,V18,T18,R18,P18,N18,L18,J18) -> 0 | AY18: =SUM(AW18,AU18,AS18,AQ18,AO18,AM18,AK18,AI18,AG18,AE18,AC18,AA18,Y18,W18,U18,S18,Q18,O18,M18,K18) -> 0 | AZ18: =(F18+G18)-AX18 -> 0 | BA18: =I18-AY18 -> 0
B19: 5045500021 | C19: =IFERROR(IF(B19,VLOOKUP((AEO!$B$13&AEO!$C$13&B19&E19),MSRV5!A:F,6,0),""),"N/A") -> 370 | D19: DESMOBIL 201 A 400KM EQP 5H RESIT OHM LD | E19: =IF(B19,VLOOKUP(B19,MSRV5!B:D,3,0),"") -> CDA | H19: =IFERROR(IF(B19,VLOOKUP((AEO!$B$13&AEO!$C$13&B19&E19),MSRV5!A:E,5,0),""),0) -> 200.33 | I19: =(F19+G19)*H19 -> 0 | K19: =J19*$H19 -> 0 | M19: =L19*$H19 -> 0 | O19: =N19*$H19 -> 0 | Q19: =P19*$H19 -> 0 | S19: =R19*$H19 -> 0 | U19: =T19*$H19 -> 0 | W19: =V19*$H19 -> 0 | Y19: =X19*$H19 -> 0 | AA19: =Z19*$H19 -> 0 | AC19: =AB19*$H19 -> 0 | AE19: =AD19*$H19 -> 0 | AG19: =AF19*$H19 -> 0 | AI19: =AH19*$H19 -> 0 | AK19: =AJ19*$H19 -> 0 | AM19: =AL19*$H19 -> 0 | AO19: =AN19*$H19 -> 0 | AQ19: =AP19*$H19 -> 0 | AS19: =AR19*$H19 -> 0 | AU19: =AT19*$H19 -> 0 | AW19: =AV19*$H19 -> 0 | AX19: =SUM(AV19,AT19,AR19,AP19,AN19,AL19,AJ19,AH19,AF19,AD19,AB19,Z19,X19,V19,T19,R19,P19,N19,L19,J19) -> 0 | AY19: =SUM(AW19,AU19,AS19,AQ19,AO19,AM19,AK19,AI19,AG19,AE19,AC19,AA19,Y19,W19,U19,S19,Q19,O19,M19,K19) -> 0 | AZ19: =(F19+G19)-AX19 -> 0 | BA19: =I19-AY19 -> 0
B20: 5045500022 | C20: =IFERROR(IF(B20,VLOOKUP((AEO!$B$13&AEO!$C$13&B20&E20),MSRV5!A:F,6,0),""),"N/A") -> 380 | D20: DESMOBIL 201 A 400KM EQP 5H SERV TEC LD | E20: =IF(B20,VLOOKUP(B20,MSRV5!B:D,3,0),"") -> CDA | H20: =IFERROR(IF(B20,VLOOKUP((AEO!$B$13&AEO!$C$13&B20&E20),MSRV5!A:E,5,0),""),0) -> 18.86 | I20: =(F20+G20)*H20 -> 0 | K20: =J20*$H20 -> 0 | M20: =L20*$H20 -> 0 | O20: =N20*$H20 -> 0 | Q20: =P20*$H20 -> 0 | S20: =R20*$H20 -> 0 | U20: =T20*$H20 -> 0 | W20: =V20*$H20 -> 0 | Y20: =X20*$H20 -> 0 | AA20: =Z20*$H20 -> 0 | AC20: =AB20*$H20 -> 0 | AE20: =AD20*$H20 -> 0 | AG20: =AF20*$H20 -> 0 | AI20: =AH20*$H20 -> 0 | AK20: =AJ20*$H20 -> 0 | AM20: =AL20*$H20 -> 0 | AO20: =AN20*$H20 -> 0 | AQ20: =AP20*$H20 -> 0 | AS20: =AR20*$H20 -> 0 | AU20: =AT20*$H20 -> 0 | AW20: =AV20*$H20 -> 0 | AX20: =SUM(AV20,AT20,AR20,AP20,AN20,AL20,AJ20,AH20,AF20,AD20,AB20,Z20,X20,V20,T20,R20,P20,N20,L20,J20) -> 0 | AY20: =SUM(AW20,AU20,AS20,AQ20,AO20,AM20,AK20,AI20,AG20,AE20,AC20,AA20,Y20,W20,U20,S20,Q20,O20,M20,K20) -> 0 | AZ20: =(F20+G20)-AX20 -> 0 | BA20: =I20-AY20 -> 0
B21: 5045500023 | C21: =IFERROR(IF(B21,VLOOKUP((AEO!$B$13&AEO!$C$13&B21&E21),MSRV5!A:F,6,0),""),"N/A") -> 390 | D21: DESMOBIL 401 A 600KM EQP 5H RESIT OHM LD | E21: =IF(B21,VLOOKUP(B21,MSRV5!B:D,3,0),"") -> CDA | H21: =IFERROR(IF(B21,VLOOKUP((AEO!$B$13&AEO!$C$13&B21&E21),MSRV5!A:E,5,0),""),0) -> 282.79 | I21: =(F21+G21)*H21 -> 0 | K21: =J21*$H21 -> 0 | M21: =L21*$H21 -> 0 | O21: =N21*$H21 -> 0 | Q21: =P21*$H21 -> 0 | S21: =R21*$H21 -> 0 | U21: =T21*$H21 -> 0 | W21: =V21*$H21 -> 0 | Y21: =X21*$H21 -> 0 | AA21: =Z21*$H21 -> 0 | AC21: =AB21*$H21 -> 0 | AE21: =AD21*$H21 -> 0 | AG21: =AF21*$H21 -> 0 | AI21: =AH21*$H21 -> 0 | AK21: =AJ21*$H21 -> 0 | AM21: =AL21*$H21 -> 0 | AO21: =AN21*$H21 -> 0 | AQ21: =AP21*$H21 -> 0 | AS21: =AR21*$H21 -> 0 | AU21: =AT21*$H21 -> 0 | AW21: =AV21*$H21 -> 0 | AX21: =SUM(AV21,AT21,AR21,AP21,AN21,AL21,AJ21,AH21,AF21,AD21,AB21,Z21,X21,V21,T21,R21,P21,N21,L21,J21) -> 0 | AY21: =SUM(AW21,AU21,AS21,AQ21,AO21,AM21,AK21,AI21,AG21,AE21,AC21,AA21,Y21,W21,U21,S21,Q21,O21,M21,K21) -> 0 | AZ21: =(F21+G21)-AX21 -> 0 | BA21: =I21-AY21 -> 0
B22: 5045500024 | C22: =IFERROR(IF(B22,VLOOKUP((AEO!$B$13&AEO!$C$13&B22&E22),MSRV5!A:F,6,0),""),"N/A") -> 400 | D22: DESMOBIL 401 A 600KM EQP 5H SERV TEC LD | E22: =IF(B22,VLOOKUP(B22,MSRV5!B:D,3,0),"") -> CDA | H22: =IFERROR(IF(B22,VLOOKUP((AEO!$B$13&AEO!$C$13&B22&E22),MSRV5!A:E,5,0),""),0) -> 282.79 | I22: =(F22+G22)*H22 -> 0 | K22: =J22*$H22 -> 0 | M22: =L22*$H22 -> 0 | O22: =N22*$H22 -> 0 | Q22: =P22*$H22 -> 0 | S22: =R22*$H22 -> 0 | U22: =T22*$H22 -> 0 | W22: =V22*$H22 -> 0 | Y22: =X22*$H22 -> 0 | AA22: =Z22*$H22 -> 0 | AC22: =AB22*$H22 -> 0 | AE22: =AD22*$H22 -> 0 | AG22: =AF22*$H22 -> 0 | AI22: =AH22*$H22 -> 0 | AK22: =AJ22*$H22 -> 0 | AM22: =AL22*$H22 -> 0 | AO22: =AN22*$H22 -> 0 | AQ22: =AP22*$H22 -> 0 | AS22: =AR22*$H22 -> 0 | AU22: =AT22*$H22 -> 0 | AW22: =AV22*$H22 -> 0 | AX22: =SUM(AV22,AT22,AR22,AP22,AN22,AL22,AJ22,AH22,AF22,AD22,AB22,Z22,X22,V22,T22,R22,P22,N22,L22,J22) -> 0 | AY22: =SUM(AW22,AU22,AS22,AQ22,AO22,AM22,AK22,AI22,AG22,AE22,AC22,AA22,Y22,W22,U22,S22,Q22,O22,M22,K22) -> 0 | AZ22: =(F22+G22)-AX22 -> 0 | BA22: =I22-AY22 -> 0
B23: 5045500030 | C23: =IFERROR(IF(B23,VLOOKUP((AEO!$B$13&AEO!$C$13&B23&E23),MSRV5!A:F,6,0),""),"N/A") -> 410 | D23: DESMOBILIZAR 201 A 400KM EQP 5H SOND LD | E23: =IF(B23,VLOOKUP(B23,MSRV5!B:D,3,0),"") -> CDA | H23: =IFERROR(IF(B23,VLOOKUP((AEO!$B$13&AEO!$C$13&B23&E23),MSRV5!A:E,5,0),""),0) -> 301.64 | I23: =(F23+G23)*H23 -> 0 | K23: =J23*$H23 -> 0 | M23: =L23*$H23 -> 0 | O23: =N23*$H23 -> 0 | Q23: =P23*$H23 -> 0 | S23: =R23*$H23 -> 0 | U23: =T23*$H23 -> 0 | W23: =V23*$H23 -> 0 | Y23: =X23*$H23 -> 0 | AA23: =Z23*$H23 -> 0 | AC23: =AB23*$H23 -> 0 | AE23: =AD23*$H23 -> 0 | AG23: =AF23*$H23 -> 0 | AI23: =AH23*$H23 -> 0 | AK23: =AJ23*$H23 -> 0 | AM23: =AL23*$H23 -> 0 | AO23: =AN23*$H23 -> 0 | AQ23: =AP23*$H23 -> 0 | AS23: =AR23*$H23 -> 0 | AU23: =AT23*$H23 -> 0 | AW23: =AV23*$H23 -> 0 | AX23: =SUM(AV23,AT23,AR23,AP23,AN23,AL23,AJ23,AH23,AF23,AD23,AB23,Z23,X23,V23,T23,R23,P23,N23,L23,J23) -> 0 | AY23: =SUM(AW23,AU23,AS23,AQ23,AO23,AM23,AK23,AI23,AG23,AE23,AC23,AA23,Y23,W23,U23,S23,Q23,O23,M23,K23) -> 0 | AZ23: =(F23+G23)-AX23 -> 0 | BA23: =I23-AY23 -> 0
B24: 5045500031 | C24: =IFERROR(IF(B24,VLOOKUP((AEO!$B$13&AEO!$C$13&B24&E24),MSRV5!A:F,6,0),""),"N/A") -> 420 | D24: DESMOBILIZAR 201 A 400KM EQP 5H TOPOG LD | E24: =IF(B24,VLOOKUP(B24,MSRV5!B:D,3,0),"") -> CDA | H24: =IFERROR(IF(B24,VLOOKUP((AEO!$B$13&AEO!$C$13&B24&E24),MSRV5!A:E,5,0),""),0) -> 2592.28 | I24: =(F24+G24)*H24 -> 0 | K24: =J24*$H24 -> 0 | M24: =L24*$H24 -> 0 | O24: =N24*$H24 -> 0 | Q24: =P24*$H24 -> 0 | S24: =R24*$H24 -> 0 | U24: =T24*$H24 -> 0 | W24: =V24*$H24 -> 0 | Y24: =X24*$H24 -> 0 | AA24: =Z24*$H24 -> 0 | AC24: =AB24*$H24 -> 0 | AE24: =AD24*$H24 -> 0 | AG24: =AF24*$H24 -> 0 | AI24: =AH24*$H24 -> 0 | AK24: =AJ24*$H24 -> 0 | AM24: =AL24*$H24 -> 0 | AO24: =AN24*$H24 -> 0 | AQ24: =AP24*$H24 -> 0 | AS24: =AR24*$H24 -> 0 | AU24: =AT24*$H24 -> 0 | AW24: =AV24*$H24 -> 0 | AX24: =SUM(AV24,AT24,AR24,AP24,AN24,AL24,AJ24,AH24,AF24,AD24,AB24,Z24,X24,V24,T24,R24,P24,N24,L24,J24) -> 0 | AY24: =SUM(AW24,AU24,AS24,AQ24,AO24,AM24,AK24,AI24,AG24,AE24,AC24,AA24,Y24,W24,U24,S24,Q24,O24,M24,K24) -> 0 | AZ24: =(F24+G24)-AX24 -> 0 | BA24: =I24-AY24 -> 0
... B49: 5056000041 | C49: =IFERROR(IF(B49,VLOOKUP((AEO!$B$13&AEO!$C$13&B49&E49),MSRV5!A:F,6,0),""),"N/A") -> 2450 | D49: DESMOB EQUIPE E MAQ. DE 201KM A 400KM | E49: =IF(B49,VLOOKUP(B49,MSRV5!B:D,3,0),"") -> KM | H49: =IFERROR(IF(B49,VLOOKUP((AEO!$B$13&AEO!$C$13&B49&E49),MSRV5!A:E,5,0),""),0) -> 15.51 | I49: =(F49+G49)*H49 -> 0 | K49: =J49*$H49 -> 0 | M49: =L49*$H49 -> 0 | O49: =N49*$H49 -> 0 | Q49: =P49*$H49 -> 0 | S49: =R49*$H49 -> 0 | U49: =T49*$H49 -> 0 | W49: =V49*$H49 -> 0 | Y49: =X49*$H49 -> 0 | AA49: =Z49*$H49 -> 0 | AC49: =AB49*$H49 -> 0 | AE49: =AD49*$H49 -> 0 | AG49: =AF49*$H49 -> 0 | AI49: =AH49*$H49 -> 0 | AK49: =AJ49*$H49 -> 0 | AM49: =AL49*$H49 -> 0 | AO49: =AN49*$H49 -> 0 | AQ49: =AP49*$H49 -> 0 | AS49: =AR49*$H49 -> 0 | AU49: =AT49*$H49 -> 0 | AW49: =AV49*$H49 -> 0 | AX49: =SUM(AV49,AT49,AR49,AP49,AN49,AL49,AJ49,AH49,AF49,AD49,AB49,Z49,X49,V49,T49,R49,P49,N49,L49,J49) -> 0 | AY49: =SUM(AW49,AU49,AS49,AQ49,AO49,AM49,AK49,AI49,AG49,AE49,AC49,AA49,Y49,W49,U49,S49,Q49,O49,M49,K49) -> 0 | AZ49: =(F49+G49)-AX49 -> 0 | BA49: =I49-AY49 -> 0
B50: 5056000043 | C50: =IFERROR(IF(B50,VLOOKUP((AEO!$B$13&AEO!$C$13&B50&E50),MSRV5!A:F,6,0),""),"N/A") -> 2460 | D50: DESMOB. S. PEQ. PORTE, DUR. MÁX. DE 30 D | E50: =IF(B50,VLOOKUP(B50,MSRV5!B:D,3,0),"") -> UA | F50: 1 | H50: =IFERROR(IF(B50,VLOOKUP((AEO!$B$13&AEO!$C$13&B50&E50),MSRV5!A:E,5,0),""),0) -> 2452.74 | I50: =(F50+G50)*H50 -> 2452.74 | K50: =J50*$H50 -> 0 | M50: =L50*$H50 -> 0 | O50: =N50*$H50 -> 0 | Q50: =P50*$H50 -> 0 | S50: =R50*$H50 -> 0 | U50: =T50*$H50 -> 0 | W50: =V50*$H50 -> 0 | Y50: =X50*$H50 -> 0 | AA50: =Z50*$H50 -> 0 | AC50: =AB50*$H50 -> 0 | AE50: =AD50*$H50 -> 0 | AG50: =AF50*$H50 -> 0 | AI50: =AH50*$H50 -> 0 | AK50: =AJ50*$H50 -> 0 | AM50: =AL50*$H50 -> 0 | AO50: =AN50*$H50 -> 0 | AQ50: =AP50*$H50 -> 0 | AS50: =AR50*$H50 -> 0 | AU50: =AT50*$H50 -> 0 | AW50: =AV50*$H50 -> 0 | AX50: =SUM(AV50,AT50,AR50,AP50,AN50,AL50,AJ50,AH50,AF50,AD50,AB50,Z50,X50,V50,T50,R50,P50,N50,L50,J50) -> 0 | AY50: =SUM(AW50,AU50,AS50,AQ50,AO50,AM50,AK50,AI50,AG50,AE50,AC50,AA50,Y50,W50,U50,S50,Q50,O50,M50,K50) -> 0 | AZ50: =(F50+G50)-AX50 -> 1 | BA50: =I50-AY50 -> 2452.74
B51: 5056000044 | C51: =IFERROR(IF(B51,VLOOKUP((AEO!$B$13&AEO!$C$13&B51&E51),MSRV5!A:F,6,0),""),"N/A") -> 2470 | D51: DESMOB. SERV. GRANDE PORTE DUR. >120 D | E51: =IF(B51,VLOOKUP(B51,MSRV5!B:D,3,0),"") -> UA | H51: =IFERROR(IF(B51,VLOOKUP((AEO!$B$13&AEO!$C$13&B51&E51),MSRV5!A:E,5,0),""),0) -> 11355.23 | I51: =(F51+G51)*H51 -> 0 | K51: =J51*$H51 -> 0 | M51: =L51*$H51 -> 0 | O51: =N51*$H51 -> 0 | Q51: =P51*$H51 -> 0 | S51: =R51*$H51 -> 0 | U51: =T51*$H51 -> 0 | W51: =V51*$H51 -> 0 | Y51: =X51*$H51 -> 0 | AA51: =Z51*$H51 -> 0 | AC51: =AB51*$H51 -> 0 | AE51: =AD51*$H51 -> 0 | AG51: =AF51*$H51 -> 0 | AI51: =AH51*$H51 -> 0 | AK51: =AJ51*$H51 -> 0 | AM51: =AL51*$H51 -> 0 | AO51: =AN51*$H51 -> 0 | AQ51: =AP51*$H51 -> 0 | AS51: =AR51*$H51 -> 0 | AU51: =AT51*$H51 -> 0 | AW51: =AV51*$H51 -> 0 | AX51: =SUM(AV51,AT51,AR51,AP51,AN51,AL51,AJ51,AH51,AF51,AD51,AB51,Z51,X51,V51,T51,R51,P51,N51,L51,J51) -> 0 | AY51: =SUM(AW51,AU51,AS51,AQ51,AO51,AM51,AK51,AI51,AG51,AE51,AC51,AA51,Y51,W51,U51,S51,Q51,O51,M51,K51) -> 0 | AZ51: =(F51+G51)-AX51 -> 0 | BA51: =I51-AY51 -> 0
B52: 5056000045 | C52: =IFERROR(IF(B52,VLOOKUP((AEO!$B$13&AEO!$C$13&B52&E52),MSRV5!A:F,6,0),""),"N/A") -> 2480 | D52: DESMOB. SER. MÉD. PORTE DUR. >60 E <120D | E52: =IF(B52,VLOOKUP(B52,MSRV5!B:D,3,0),"") -> UA | H52: =IFERROR(IF(B52,VLOOKUP((AEO!$B$13&AEO!$C$13&B52&E52),MSRV5!A:E,5,0),""),0) -> 5826.63 | I52: =(F52+G52)*H52 -> 0 | K52: =J52*$H52 -> 0 | M52: =L52*$H52 -> 0 | O52: =N52*$H52 -> 0 | Q52: =P52*$H52 -> 0 | S52: =R52*$H52 -> 0 | U52: =T52*$H52 -> 0 | W52: =V52*$H52 -> 0 | Y52: =X52*$H52 -> 0 | AA52: =Z52*$H52 -> 0 | AC52: =AB52*$H52 -> 0 | AE52: =AD52*$H52 -> 0 | AG52: =AF52*$H52 -> 0 | AI52: =AH52*$H52 -> 0 | AK52: =AJ52*$H52 -> 0 | AM52: =AL52*$H52 -> 0 | AO52: =AN52*$H52 -> 0 | AQ52: =AP52*$H52 -> 0 | AS52: =AR52*$H52 -> 0 | AU52: =AT52*$H52 -> 0 | AW52: =AV52*$H52 -> 0 | AX52: =SUM(AV52,AT52,AR52,AP52,AN52,AL52,AJ52,AH52,AF52,AD52,AB52,Z52,X52,V52,T52,R52,P52,N52,L52,J52) -> 0 | AY52: =SUM(AW52,AU52,AS52,AQ52,AO52,AM52,AK52,AI52,AG52,AE52,AC52,AA52,Y52,W52,U52,S52,Q52,O52,M52,K52) -> 0 | AZ52: =(F52+G52)-AX52 -> 0 | BA52: =I52-AY52 -> 0
B53: 5056000046 | C53: =IFERROR(IF(B53,VLOOKUP((AEO!$B$13&AEO!$C$13&B53&E53),MSRV5!A:F,6,0),""),"N/A") -> 2490 | D53: DESMOB. SERV. PEQ. PORTE, DUR. MÁX. 60D | E53: =IF(B53,VLOOKUP(B53,MSRV5!B:D,3,0),"") -> UA | H53: =IFERROR(IF(B53,VLOOKUP((AEO!$B$13&AEO!$C$13&B53&E53),MSRV5!A:E,5,0),""),0) -> 2987.82 | I53: =(F53+G53)*H53 -> 0 | K53: =J53*$H53 -> 0 | M53: =L53*$H53 -> 0 | O53: =N53*$H53 -> 0 | Q53: =P53*$H53 -> 0 | S53: =R53*$H53 -> 0 | U53: =T53*$H53 -> 0 | W53: =V53*$H53 -> 0 | Y53: =X53*$H53 -> 0 | AA53: =Z53*$H53 -> 0 | AC53: =AB53*$H53 -> 0 | AE53: =AD53*$H53 -> 0 | AG53: =AF53*$H53 -> 0 | AI53: =AH53*$H53 -> 0 | AK53: =AJ53*$H53 -> 0 | AM53: =AL53*$H53 -> 0 | AO53: =AN53*$H53 -> 0 | AQ53: =AP53*$H53 -> 0 | AS53: =AR53*$H53 -> 0 | AU53: =AT53*$H53 -> 0 | AW53: =AV53*$H53 -> 0 | AX53: =SUM(AV53,AT53,AR53,AP53,AN53,AL53,AJ53,AH53,AF53,AD53,AB53,Z53,X53,V53,T53,R53,P53,N53,L53,J53) -> 0 | AY53: =SUM(AW53,AU53,AS53,AQ53,AO53,AM53,AK53,AI53,AG53,AE53,AC53,AA53,Y53,W53,U53,S53,Q53,O53,M53,K53) -> 0 | AZ53: =(F53+G53)-AX53 -> 0 | BA53: =I53-AY53 -> 0
B54: 5056000059 | C54: =IFERROR(IF(B54,VLOOKUP((AEO!$B$13&AEO!$C$13&B54&E54),MSRV5!A:F,6,0),""),"N/A") -> 2540 | D54: MOBIL. SER. PEQ. PORTE, DUR. MÁX. DE 30D | E54: =IF(B54,VLOOKUP(B54,MSRV5!B:D,3,0),"") -> UA | F54: 1 | H54: =IFERROR(IF(B54,VLOOKUP((AEO!$B$13&AEO!$C$13&B54&E54),MSRV5!A:E,5,0),""),0) -> 8346.53 | I54: =(F54+G54)*H54 -> 8346.53 | J54: 1 | K54: =J54*$H54 -> 8346.53 | M54: =L54*$H54 -> 0 | O54: =N54*$H54 -> 0 | Q54: =P54*$H54 -> 0 | S54: =R54*$H54 -> 0 | U54: =T54*$H54 -> 0 | W54: =V54*$H54 -> 0 | Y54: =X54*$H54 -> 0 | AA54: =Z54*$H54 -> 0 | AC54: =AB54*$H54 -> 0 | AE54: =AD54*$H54 -> 0 | AG54: =AF54*$H54 -> 0 | AI54: =AH54*$H54 -> 0 | AK54: =AJ54*$H54 -> 0 | AM54: =AL54*$H54 -> 0 | AO54: =AN54*$H54 -> 0 | AQ54: =AP54*$H54 -> 0 | AS54: =AR54*$H54 -> 0 | AU54: =AT54*$H54 -> 0 | AW54: =AV54*$H54 -> 0 | AX54: =SUM(AV54,AT54,AR54,AP54,AN54,AL54,AJ54,AH54,AF54,AD54,AB54,Z54,X54,V54,T54,R54,P54,N54,L54,J54) -> 1 | AY54: =SUM(AW54,AU54,AS54,AQ54,AO54,AM54,AK54,AI54,AG54,AE54,AC54,AA54,Y54,W54,U54,S54,Q54,O54,M54,K54) -> 8346.53 | AZ54: =(F54+G54)-AX54 -> 0 | BA54: =I54-AY54 -> 0
B55: 5056000060 | C55: =IFERROR(IF(B55,VLOOKUP((AEO!$B$13&AEO!$C$13&B55&E55),MSRV5!A:F,6,0),""),"N/A") -> 2550 | D55: MOBILIZAR SERV. GRANDE PORTE DUR. >120 D | E55: =IF(B55,VLOOKUP(B55,MSRV5!B:D,3,0),"") -> UA | H55: =IFERROR(IF(B55,VLOOKUP((AEO!$B$13&AEO!$C$13&B55&E55),MSRV5!A:E,5,0),""),0) -> 28413.53 | I55: =(F55+G55)*H55 -> 0 | K55: =J55*$H55 -> 0 | M55: =L55*$H55 -> 0 | O55: =N55*$H55 -> 0 | Q55: =P55*$H55 -> 0 | S55: =R55*$H55 -> 0 | U55: =T55*$H55 -> 0 | W55: =V55*$H55 -> 0 | Y55: =X55*$H55 -> 0 | AA55: =Z55*$H55 -> 0 | AC55: =AB55*$H55 -> 0 | AE55: =AD55*$H55 -> 0 | AG55: =AF55*$H55 -> 0 | AI55: =AH55*$H55 -> 0 | AK55: =AJ55*$H55 -> 0 | AM55: =AL55*$H55 -> 0 | AO55: =AN55*$H55 -> 0 | AQ55: =AP55*$H55 -> 0 | AS55: =AR55*$H55 -> 0 | AU55: =AT55*$H55 -> 0 | AW55: =AV55*$H55 -> 0 | AX55: =SUM(AV55,AT55,AR55,AP55,AN55,AL55,AJ55,AH55,AF55,AD55,AB55,Z55,X55,V55,T55,R55,P55,N55,L55,J55) -> 0 | AY55: =SUM(AW55,AU55,AS55,AQ55,AO55,AM55,AK55,AI55,AG55,AE55,AC55,AA55,Y55,W55,U55,S55,Q55,O55,M55,K55) -> 0 | AZ55: =(F55+G55)-AX55 -> 0 | BA55: =I55-AY55 -> 0
B56: 5056000061 | C56: =IFERROR(IF(B56,VLOOKUP((AEO!$B$13&AEO!$C$13&B56&E56),MSRV5!A:F,6,0),""),"N/A") -> 2560 | D56: MOBIL. SERV. MÉD. PORTE DUR. >60 E <120D | E56: =IF(B56,VLOOKUP(B56,MSRV5!B:D,3,0),"") -> UA | H56: =IFERROR(IF(B56,VLOOKUP((AEO!$B$13&AEO!$C$13&B56&E56),MSRV5!A:E,5,0),""),0) -> 16316.99 | I56: =(F56+G56)*H56 -> 0 | K56: =J56*$H56 -> 0 | M56: =L56*$H56 -> 0 | O56: =N56*$H56 -> 0 | Q56: =P56*$H56 -> 0 | S56: =R56*$H56 -> 0 | U56: =T56*$H56 -> 0 | W56: =V56*$H56 -> 0 | Y56: =X56*$H56 -> 0 | AA56: =Z56*$H56 -> 0 | AC56: =AB56*$H56 -> 0 | AE56: =AD56*$H56 -> 0 | AG56: =AF56*$H56 -> 0 | AI56: =AH56*$H56 -> 0 | AK56: =AJ56*$H56 -> 0 | AM56: =AL56*$H56 -> 0 | AO56: =AN56*$H56 -> 0 | AQ56: =AP56*$H56 -> 0 | AS56: =AR56*$H56 -> 0 | AU56: =AT56*$H56 -> 0 | AW56: =AV56*$H56 -> 0 | AX56: =SUM(AV56,AT56,AR56,AP56,AN56,AL56,AJ56,AH56,AF56,AD56,AB56,Z56,X56,V56,T56,R56,P56,N56,L56,J56) -> 0 | AY56: =SUM(AW56,AU56,AS56,AQ56,AO56,AM56,AK56,AI56,AG56,AE56,AC56,AA56,Y56,W56,U56,S56,Q56,O56,M56,K56) -> 0 | AZ56: =(F56+G56)-AX56 -> 0 | BA56: =I56-AY56 -> 0
B57: 5056000062 | C57: =IFERROR(IF(B57,VLOOKUP((AEO!$B$13&AEO!$C$13&B57&E57),MSRV5!A:F,6,0),""),"N/A") -> 2570 | D57: MOBILIZ. SER. PEQ. PORTE, DUR. MÁX. 60D | E57: =IF(B57,VLOOKUP(B57,MSRV5!B:D,3,0),"") -> UA | H57: =IFERROR(IF(B57,VLOOKUP((AEO!$B$13&AEO!$C$13&B57&E57),MSRV5!A:E,5,0),""),0) -> 10300.5 | I57: =(F57+G57)*H57 -> 0 | K57: =J57*$H57 -> 0 | M57: =L57*$H57 -> 0 | O57: =N57*$H57 -> 0 | Q57: =P57*$H57 -> 0 | S57: =R57*$H57 -> 0 | U57: =T57*$H57 -> 0 | W57: =V57*$H57 -> 0 | Y57: =X57*$H57 -> 0 | AA57: =Z57*$H57 -> 0 | AC57: =AB57*$H57 -> 0 | AE57: =AD57*$H57 -> 0 | AG57: =AF57*$H57 -> 0 | AI57: =AH57*$H57 -> 0 | AK57: =AJ57*$H57 -> 0 | AM57: =AL57*$H57 -> 0 | AO57: =AN57*$H57 -> 0 | AQ57: =AP57*$H57 -> 0 | AS57: =AR57*$H57 -> 0 | AU57: =AT57*$H57 -> 0 | AW57: =AV57*$H57 -> 0 | AX57: =SUM(AV57,AT57,AR57,AP57,AN57,AL57,AJ57,AH57,AF57,AD57,AB57,Z57,X57,V57,T57,R57,P57,N57,L57,J57) -> 0 | AY57: =SUM(AW57,AU57,AS57,AQ57,AO57,AM57,AK57,AI57,AG57,AE57,AC57,AA57,Y57,W57,U57,S57,Q57,O57,M57,K57) -> 0 | AZ57: =(F57+G57)-AX57 -> 0 | BA57: =I57-AY57 -> 0
B58: 5500300165 | C58: =IFERROR(IF(B58,VLOOKUP((AEO!$B$13&AEO!$C$13&B58&E58),MSRV5!A:F,6,0),""),"N/A") -> 7070 | D58: LOCAÇÃO, MARCAÇÃO E ACOMPANHAM. DA OBRA | E58: =IF(B58,VLOOKUP(B58,MSRV5!B:D,3,0),"") -> UN | H58: =IFERROR(IF(B58,VLOOKUP((AEO!$B$13&AEO!$C$13&B58&E58),MSRV5!A:E,5,0),""),0) -> 13662.94 | I58: =(F58+G58)*H58 -> 0 | K58: =J58*$H58 -> 0 | M58: =L58*$H58 -> 0 | O58: =N58*$H58 -> 0 | Q58: =P58*$H58 -> 0 | S58: =R58*$H58 -> 0 | U58: =T58*$H58 -> 0 | W58: =V58*$H58 -> 0 | Y58: =X58*$H58 -> 0 | AA58: =Z58*$H58 -> 0 | AC58: =AB58*$H58 -> 0 | AE58: =AD58*$H58 -> 0 | AG58: =AF58*$H58 -> 0 | AI58: =AH58*$H58 -> 0 | AK58: =AJ58*$H58 -> 0 | AM58: =AL58*$H58 -> 0 | AO58: =AN58*$H58 -> 0 | AQ58: =AP58*$H58 -> 0 | AS58: =AR58*$H58 -> 0 | AU58: =AT58*$H58 -> 0 | AW58: =AV58*$H58 -> 0 | AX58: =SUM(AV58,AT58,AR58,AP58,AN58,AL58,AJ58,AH58,AF58,AD58,AB58,Z58,X58,V58,T58,R58,P58,N58,L58,J58) -> 0 | AY58: =SUM(AW58,AU58,AS58,AQ58,AO58,AM58,AK58,AI58,AG58,AE58,AC58,AA58,Y58,W58,U58,S58,Q58,O58,M58,K58) -> 0 | AZ58: =(F58+G58)-AX58 -> 0 | BA58: =I58-AY58 -> 0
B59: 5053000017 | C59: =IFERROR(IF(B59,VLOOKUP((AEO!$B$13&AEO!$C$13&B59&E59),MSRV5!A:F,6,0),""),"N/A") -> 1850 | D59: LIGAÇÃO PROVISÓRIA DE LUZ E FORÇA P/ SE | E59: =IF(B59,VLOOKUP(B59,MSRV5!B:D,3,0),"") -> UN | H59: =IFERROR(IF(B59,VLOOKUP((AEO!$B$13&AEO!$C$13&B59&E59),MSRV5!A:E,5,0),""),0) -> 4961.11 | I59: =(F59+G59)*H59 -> 0 | K59: =J59*$H59 -> 0 | M59: =L59*$H59 -> 0 | O59: =N59*$H59 -> 0 | Q59: =P59*$H59 -> 0 | S59: =R59*$H59 -> 0 | U59: =T59*$H59 -> 0 | W59: =V59*$H59 -> 0 | Y59: =X59*$H59 -> 0 | AA59: =Z59*$H59 -> 0 | AC59: =AB59*$H59 -> 0 | AE59: =AD59*$H59 -> 0 | AG59: =AF59*$H59 -> 0 | AI59: =AH59*$H59 -> 0 | AK59: =AJ59*$H59 -> 0 | AM59: =AL59*$H59 -> 0 | AO59: =AN59*$H59 -> 0 | AQ59: =AP59*$H59 -> 0 | AS59: =AR59*$H59 -> 0 | AU59: =AT59*$H59 -> 0 | AW59: =AV59*$H59 -> 0 | AX59: =SUM(AV59,AT59,AR59,AP59,AN59,AL59,AJ59,AH59,AF59,AD59,AB59,Z59,X59,V59,T59,R59,P59,N59,L59,J59) -> 0 | AY59: =SUM(AW59,AU59,AS59,AQ59,AO59,AM59,AK59,AI59,AG59,AE59,AC59,AA59,Y59,W59,U59,S59,Q59,O59,M59,K59) -> 0 | AZ59: =(F59+G59)-AX59 -> 0 | BA59: =I59-AY59 -> 0
B60: 5500300057 | C60: =IFERROR(IF(B60,VLOOKUP((AEO!$B$13&AEO!$C$13&B60&E60),MSRV5!A:F,6,0),""),"N/A") -> 6820 | D60: INSTALAÇÕES PROVIS. DE ENERGIA ELÉTRICA | E60: =IF(B60,VLOOKUP(B60,MSRV5!B:D,3,0),"") -> MES | H60: =IFERROR(IF(B60,VLOOKUP((AEO!$B$13&AEO!$C$13&B60&E60),MSRV5!A:E,5,0),""),0) -> 6112.22 | I60: =(F60+G60)*H60 -> 0 | K60: =J60*$H60 -> 0 | M60: =L60*$H60 -> 0 | O60: =N60*$H60 -> 0 | Q60: =P60*$H60 -> 0 | S60: =R60*$H60 -> 0 | U60: =T60*$H60 -> 0 | W60: =V60*$H60 -> 0 | Y60: =X60*$H60 -> 0 | AA60: =Z60*$H60 -> 0 | AC60: =AB60*$H60 -> 0 | AE60: =AD60*$H60 -> 0 | AG60: =AF60*$H60 -> 0 | AI60: =AH60*$H60 -> 0 | AK60: =AJ60*$H60 -> 0 | AM60: =AL60*$H60 -> 0 | AO60: =AN60*$H60 -> 0 | AQ60: =AP60*$H60 -> 0 | AS60: =AR60*$H60 -> 0 | AU60: =AT60*$H60 -> 0 | AW60: =AV60*$H60 -> 0 | AX60: =SUM(AV60,AT60,AR60,AP60,AN60,AL60,AJ60,AH60,AF60,AD60,AB60,Z60,X60,V60,T60,R60,P60,N60,L60,J60) -> 0 | AY60: =SUM(AW60,AU60,AS60,AQ60,AO60,AM60,AK60,AI60,AG60,AE60,AC60,AA60,Y60,W60,U60,S60,Q60,O60,M60,K60) -> 0 | AZ60: =(F60+G60)-AX60 -> 0 | BA60: =I60-AY60 -> 0
B61: 5500400469 | C61: =IFERROR(IF(B61,VLOOKUP((AEO!$B$13&AEO!$C$13&B61&E61),MSRV5!A:F,6,0),""),"N/A") -> 8770 | D61: TELA TAPUME (ISOLAMENTO/SINALIZAÇÃO) | E61: =IF(B61,VLOOKUP(B61,MSRV5!B:D,3,0),"") -> M | H61: =IFERROR(IF(B61,VLOOKUP((AEO!$B$13&AEO!$C$13&B61&E61),MSRV5!A:E,5,0),""),0) -> 19.24 | I61: =(F61+G61)*H61 -> 0 | K61: =J61*$H61 -> 0 | M61: =L61*$H61 -> 0 | O61: =N61*$H61 -> 0 | Q61: =P61*$H61 -> 0 | S61: =R61*$H61 -> 0 | U61: =T61*$H61 -> 0 | W61: =V61*$H61 -> 0 | Y61: =X61*$H61 -> 0 | AA61: =Z61*$H61 -> 0 | AC61: =AB61*$H61 -> 0 | AE61: =AD61*$H61 -> 0 | AG61: =AF61*$H61 -> 0 | AI61: =AH61*$H61 -> 0 | AK61: =AJ61*$H61 -> 0 | AM61: =AL61*$H61 -> 0 | AO61: =AN61*$H61 -> 0 | AQ61: =AP61*$H61 -> 0 | AS61: =AR61*$H61 -> 0 | AU61: =AT61*$H61 -> 0 | AW61: =AV61*$H61 -> 0 | AX61: =SUM(AV61,AT61,AR61,AP61,AN61,AL61,AJ61,AH61,AF61,AD61,AB61,Z61,X61,V61,T61,R61,P61,N61,L61,J61) -> 0 | AY61: =SUM(AW61,AU61,AS61,AQ61,AO61,AM61,AK61,AI61,AG61,AE61,AC61,AA61,Y61,W61,U61,S61,Q61,O61,M61,K61) -> 0 | AZ61: =(F61+G61)-AX61 -> 0 | BA61: =I61-AY61 -> 0
B62: 5056000008 | C62: =IFERROR(IF(B62,VLOOKUP((AEO!$B$13&AEO!$C$13&B62&E62),MSRV5!A:F,6,0),""),"N/A") -> 2430 | D62: LIMPEZA GERAL DA OBRA (CIVIL) | E62: =IF(B62,VLOOKUP(B62,MSRV5!B:D,3,0),"") -> UN | H62: =IFERROR(IF(B62,VLOOKUP((AEO!$B$13&AEO!$C$13&B62&E62),MSRV5!A:E,5,0),""),0) -> 1298.5 | I62: =(F62+G62)*H62 -> 0 | K62: =J62*$H62 -> 0 | M62: =L62*$H62 -> 0 | O62: =N62*$H62 -> 0 | Q62: =P62*$H62 -> 0 | S62: =R62*$H62 -> 0 | U62: =T62*$H62 -> 0 | W62: =V62*$H62 -> 0 | Y62: =X62*$H62 -> 0 | AA62: =Z62*$H62 -> 0 | AC62: =AB62*$H62 -> 0 | AE62: =AD62*$H62 -> 0 | AG62: =AF62*$H62 -> 0 | AI62: =AH62*$H62 -> 0 | AK62: =AJ62*$H62 -> 0 | AM62: =AL62*$H62 -> 0 | AO62: =AN62*$H62 -> 0 | AQ62: =AP62*$H62 -> 0 | AS62: =AR62*$H62 -> 0 | AU62: =AT62*$H62 -> 0 | AW62: =AV62*$H62 -> 0 | AX62: =SUM(AV62,AT62,AR62,AP62,AN62,AL62,AJ62,AH62,AF62,AD62,AB62,Z62,X62,V62,T62,R62,P62,N62,L62,J62) -> 0 | AY62: =SUM(AW62,AU62,AS62,AQ62,AO62,AM62,AK62,AI62,AG62,AE62,AC62,AA62,Y62,W62,U62,S62,Q62,O62,M62,K62) -> 0 | AZ62: =(F62+G62)-AX62 -> 0 | BA62: =I62-AY62 -> 0
B63: 5500300118 | C63: =IFERROR(IF(B63,VLOOKUP((AEO!$B$13&AEO!$C$13&B63&E63),MSRV5!A:F,6,0),""),"N/A") -> 7020 | D63: LIMPEZA INICIAL | E63: =IF(B63,VLOOKUP(B63,MSRV5!B:D,3,0),"") -> UN | H63: =IFERROR(IF(B63,VLOOKUP((AEO!$B$13&AEO!$C$13&B63&E63),MSRV5!A:E,5,0),""),0) -> 3189 | I63: =(F63+G63)*H63 -> 0 | K63: =J63*$H63 -> 0 | M63: =L63*$H63 -> 0 | O63: =N63*$H63 -> 0 | Q63: =P63*$H63 -> 0 | S63: =R63*$H63 -> 0 | U63: =T63*$H63 -> 0 | W63: =V63*$H63 -> 0 | Y63: =X63*$H63 -> 0 | AA63: =Z63*$H63 -> 0 | AC63: =AB63*$H63 -> 0 | AE63: =AD63*$H63 -> 0 | AG63: =AF63*$H63 -> 0 | AI63: =AH63*$H63 -> 0 | AK63: =AJ63*$H63 -> 0 | AM63: =AL63*$H63 -> 0 | AO63: =AN63*$H63 -> 0 | AQ63: =AP63*$H63 -> 0 | AS63: =AR63*$H63 -> 0 | AU63: =AT63*$H63 -> 0 | AW63: =AV63*$H63 -> 0 | AX63: =SUM(AV63,AT63,AR63,AP63,AN63,AL63,AJ63,AH63,AF63,AD63,AB63,Z63,X63,V63,T63,R63,P63,N63,L63,J63) -> 0 | AY63: =SUM(AW63,AU63,AS63,AQ63,AO63,AM63,AK63,AI63,AG63,AE63,AC63,AA63,Y63,W63,U63,S63,Q63,O63,M63,K63) -> 0 | AZ63: =(F63+G63)-AX63 -> 0 | BA63: =I63-AY63 -> 0
B64: 5500300058 | C64: =IFERROR(IF(B64,VLOOKUP((AEO!$B$13&AEO!$C$13&B64&E64),MSRV5!A:F,6,0),""),"N/A") -> 6830 | D64: INSTALAÇÕES PROVISÓRIAS DE ÁGUA E ESGOTO | E64: =IF(B64,VLOOKUP(B64,MSRV5!B:D,3,0),"") -> MES | H64: =IFERROR(IF(B64,VLOOKUP((AEO!$B$13&AEO!$C$13&B64&E64),MSRV5!A:E,5,0),""),0) -> 4900 | I64: =(F64+G64)*H64 -> 0 | K64: =J64*$H64 -> 0 | M64: =L64*$H64 -> 0 | O64: =N64*$H64 -> 0 | Q64: =P64*$H64 -> 0 | S64: =R64*$H64 -> 0 | U64: =T64*$H64 -> 0 | W64: =V64*$H64 -> 0 | Y64: =X64*$H64 -> 0 | AA64: =Z64*$H64 -> 0 | AC64: =AB64*$H64 -> 0 | AE64: =AD64*$H64 -> 0 | AG64: =AF64*$H64 -> 0 | AI64: =AH64*$H64 -> 0 | AK64: =AJ64*$H64 -> 0 | AM64: =AL64*$H64 -> 0 | AO64: =AN64*$H64 -> 0 | AQ64: =AP64*$H64 -> 0 | AS64: =AR64*$H64 -> 0 | AU64: =AT64*$H64 -> 0 | AW64: =AV64*$H64 -> 0 | AX64: =SUM(AV64,AT64,AR64,AP64,AN64,AL64,AJ64,AH64,AF64,AD64,AB64,Z64,X64,V64,T64,R64,P64,N64,L64,J64) -> 0 | AY64: =SUM(AW64,AU64,AS64,AQ64,AO64,AM64,AK64,AI64,AG64,AE64,AC64,AA64,Y64,W64,U64,S64,Q64,O64,M64,K64) -> 0 | AZ64: =(F64+G64)-AX64 -> 0 | BA64: =I64-AY64 -> 0
B65: 5500100842 | C65: =IFERROR(IF(B65,VLOOKUP((AEO!$B$13&AEO!$C$13&B65&E65),MSRV5!A:F,6,0),""),"N/A") -> 4940 | D65: CONSTRUIR BARRACÃO DE OBRAS | E65: =IF(B65,VLOOKUP(B65,MSRV5!B:D,3,0),"") -> M2 | H65: =IFERROR(IF(B65,VLOOKUP((AEO!$B$13&AEO!$C$13&B65&E65),MSRV5!A:E,5,0),""),0) -> 763.64 | I65: =(F65+G65)*H65 -> 0 | K65: =J65*$H65 -> 0 | M65: =L65*$H65 -> 0 | O65: =N65*$H65 -> 0 | Q65: =P65*$H65 -> 0 | S65: =R65*$H65 -> 0 | U65: =T65*$H65 -> 0 | W65: =V65*$H65 -> 0 | Y65: =X65*$H65 -> 0 | AA65: =Z65*$H65 -> 0 | AC65: =AB65*$H65 -> 0 | AE65: =AD65*$H65 -> 0 | AG65: =AF65*$H65 -> 0 | AI65: =AH65*$H65 -> 0 | AK65: =AJ65*$H65 -> 0 | AM65: =AL65*$H65 -> 0 | AO65: =AN65*$H65 -> 0 | AQ65: =AP65*$H65 -> 0 | AS65: =AR65*$H65 -> 0 | AU65: =AT65*$H65 -> 0 | AW65: =AV65*$H65 -> 0 | AX65: =SUM(AV65,AT65,AR65,AP65,AN65,AL65,AJ65,AH65,AF65,AD65,AB65,Z65,X65,V65,T65,R65,P65,N65,L65,J65) -> 0 | AY65: =SUM(AW65,AU65,AS65,AQ65,AO65,AM65,AK65,AI65,AG65,AE65,AC65,AA65,Y65,W65,U65,S65,Q65,O65,M65,K65) -> 0 | AZ65: =(F65+G65)-AX65 -> 0 | BA65: =I65-AY65 -> 0
B66: 5056000048 | C66: =IFERROR(IF(B66,VLOOKUP((AEO!$B$13&AEO!$C$13&B66&E66),MSRV5!A:F,6,0),""),"N/A") -> 2500 | D66: EMITIR ART E DOCUMENTAÇÃO DE AMPLI SE'S | E66: =IF(B66,VLOOKUP(B66,MSRV5!B:D,3,0),"") -> UA | H66: =IFERROR(IF(B66,VLOOKUP((AEO!$B$13&AEO!$C$13&B66&E66),MSRV5!A:E,5,0),""),0) -> 3839.85 | I66: =(F66+G66)*H66 -> 0 | K66: =J66*$H66 -> 0 | M66: =L66*$H66 -> 0 | O66: =N66*$H66 -> 0 | Q66: =P66*$H66 -> 0 | S66: =R66*$H66 -> 0 | U66: =T66*$H66 -> 0 | W66: =V66*$H66 -> 0 | Y66: =X66*$H66 -> 0 | AA66: =Z66*$H66 -> 0 | AC66: =AB66*$H66 -> 0 | AE66: =AD66*$H66 -> 0 | AG66: =AF66*$H66 -> 0 | AI66: =AH66*$H66 -> 0 | AK66: =AJ66*$H66 -> 0 | AM66: =AL66*$H66 -> 0 | AO66: =AN66*$H66 -> 0 | AQ66: =AP66*$H66 -> 0 | AS66: =AR66*$H66 -> 0 | AU66: =AT66*$H66 -> 0 | AW66: =AV66*$H66 -> 0 | AX66: =SUM(AV66,AT66,AR66,AP66,AN66,AL66,AJ66,AH66,AF66,AD66,AB66,Z66,X66,V66,T66,R66,P66,N66,L66,J66) -> 0 | AY66: =SUM(AW66,AU66,AS66,AQ66,AO66,AM66,AK66,AI66,AG66,AE66,AC66,AA66,Y66,W66,U66,S66,Q66,O66,M66,K66) -> 0 | AZ66: =(F66+G66)-AX66 -> 0 | BA66: =I66-AY66 -> 0
... B84: 5500000955 | C84: =IFERROR(IF(B84,VLOOKUP((AEO!$B$13&AEO!$C$13&B84&E84),MSRV5!A:F,6,0),""),"N/A") -> 3570 | D84: BARRAÇÃO REFEITÓRIO 6X6m | E84: =IF(B84,VLOOKUP(B84,MSRV5!B:D,3,0),"") -> UN | H84: =IFERROR(IF(B84,VLOOKUP((AEO!$B$13&AEO!$C$13&B84&E84),MSRV5!A:E,5,0),""),0) -> 6905.35 | I84: =(F84+G84)*H84 -> 0 | K84: =J84*$H84 -> 0 | M84: =L84*$H84 -> 0 | O84: =N84*$H84 -> 0 | Q84: =P84*$H84 -> 0 | S84: =R84*$H84 -> 0 | U84: =T84*$H84 -> 0 | W84: =V84*$H84 -> 0 | Y84: =X84*$H84 -> 0 | AA84: =Z84*$H84 -> 0 | AC84: =AB84*$H84 -> 0 | AE84: =AD84*$H84 -> 0 | AG84: =AF84*$H84 -> 0 | AI84: =AH84*$H84 -> 0 | AK84: =AJ84*$H84 -> 0 | AM84: =AL84*$H84 -> 0 | AO84: =AN84*$H84 -> 0 | AQ84: =AP84*$H84 -> 0 | AS84: =AR84*$H84 -> 0 | AU84: =AT84*$H84 -> 0 | AW84: =AV84*$H84 -> 0 | AX84: =SUM(AV84,AT84,AR84,AP84,AN84,AL84,AJ84,AH84,AF84,AD84,AB84,Z84,X84,V84,T84,R84,P84,N84,L84,J84) -> 0 | AY84: =SUM(AW84,AU84,AS84,AQ84,AO84,AM84,AK84,AI84,AG84,AE84,AC84,AA84,Y84,W84,U84,S84,Q84,O84,M84,K84) -> 0 | AZ84: =(F84+G84)-AX84 -> 0 | BA84: =I84-AY84 -> 0
...

Sheet Relatório de Evidências
D2: RELATÓRIO DE EVIDÊNCIAS DOS SERVIÇOS EXECUTADOS | N2: PERÍODO DE MEDIÇÃO
N3: 01/06/25 a 30/06/2025
B4: RESPONSÁVEL: | D4: =AEO!I34 -> GIOVANNI CENDES FINOTTI | J4: CONTATO | L4: =VLOOKUP(D4,Contratos!L:N,3,0) -> +55 62 98102-0756 | N4: SI / AES | P4: =AEO!L3 -> 03396-26
B5: EMPRESA | D5: =AEO!D13 -> ENERGY SYSTEN CONSTRUCOES E MANUTEN | J5: CONTRATO | L5: =AEO!B13 -> 4600027637 | N5: RC
B7: OBJETIVO | J7: REGISTRO FOTOGRÁFICO
B8: Comprovar a execuçãdo dos serviços prestados, bem como subsdiar a validação pela empresa contratante da medição (atividade/quantidade) e a qualidade dos referidos serviços. | J8: Fazer o registro de forma à se obter as comprovações devidas de acordo com as medições apresentadas tendo nas fotos o registro de data, coordenada da foto e nome da obra
B10: A | C10: ...Passo para inserir a foto | F10: B | G10: ...Passo para selecionar a foto | J10: C | K10: ...Passo para iniciar formatar | N10: D | O10: ...Passo para conf. tamanho
B11: Clique no campo onde deseja colar a foto, após |1| clique na Aba [Inserir] e em seguida |2| clique em Imagem... | F11: |3| Localize a pasta na qual está a foto, |4| selecione a foto desejada e |5| clique em [Inserir]... | J11: |6| Clique na foto inserida, em seguida |7|clique na Aba [Ferramentas de Imagem] e após |8| clique no icone |Tamanho|... | N11: ...tela aberta na parte |Tamanho e rotação| desmarque as |9| opções Fixar taxa... |10| e Relativo ao.., em seguida configura a |11| altura=9,6 e |12| largura=12,8...
B13: EVIDÊNCIAS FOTOGRÁFICAS
B14: 1 | C14: 5056000059 | D14: MOBIL. SER. PEQ. PORTE, DUR. MÁX. DE 30D | J14: OBS:
B16: ENQUADRAR A FOTO À ESSE ESPAÇO, OBEDECENDO AS DIMENSÕES. Para inserir e configurar a foto, siga as orientações que se encontram no campo passo-a-passo, caso esteja oculto, clique no [2] ao lado da coluna A do cabeçalho para reexibir.
B36: 2 | C36: 5054000014 | D36: EXECUTAR INTERLIGAÇÃO DE RELIGADOR | J36: OBS: | K36: 4124R
B38: ENQUADRAR A FOTO À ESSE ESPAÇO, OBEDECENDO AS DIMENSÕES. Para inserir e configurar a foto, siga as orientações que se encontram no campo passo-a-passo, caso esteja oculto, clique no [2] ao lado da coluna A do cabeçalho para reexibir.
B59: 3 | C59: 5054000015 | D59: EXECUTAR INTERLIGAÇÃO TR COM AUTOMAÇÃO | J59: OBS: | K59: TR2
B61: ENQUADRAR A FOTO À ESSE ESPAÇO, OBEDECENDO AS DIMENSÕES. Para inserir e configurar a foto, siga as orientações que se encontram no campo passo-a-passo, caso esteja oculto, clique no [2] ao lado da coluna A do cabeçalho para reexibir.
B81: 4 | C81: 5054000050 | D81: INTERLIGAR RELÉ MONTADO EM PAINEL | J81: OBS: | K81: RF4
B103: 5 | C103: 5054200003 | D103: EXEC INSTALAÇÃO COMPONENTES AUXILIARES | J103: OBS: | K103: RF4
B126: 6 | C126: 5054000029 | D126: ADEQUAÇÃO FIAÇÃO RELÉ PAINEL PROTEÇÃO | J126: OBS:
B128: ENQUADRAR A FOTO À ESSE ESPAÇO, OBEDECENDO AS DIMENSÕES. Para inserir e configurar a foto, siga as orientações que se encontram no campo passo-a-passo, caso esteja oculto, clique no [2] ao lado da coluna A do cabeçalho para reexibir.
B148: 7 | C148: 5054000023 | D148: LANÇAR CABOS ATÉ 10 CONDUTORES | J148: OBS:
B170: 8 | C170: 5054100005 | D170: LANÇAR CABO DE FIBRA ÓPTICA | J170: OBS:
B172: ENQUADRAR A FOTO À ESSE ESPAÇO, OBEDECENDO AS DIMENSÕES. Para inserir e configurar a foto, siga as orientações que se encontram no campo passo-a-passo, caso esteja oculto, clique no [2] ao lado da coluna A do cabeçalho para reexibir.
B193: 9 | C193: 5054100006 | D193: LANÇAMENTO DE CORDÃO DE FIBRA ÓPTICA | J193: OBS:
B195: ENQUADRAR A FOTO À ESSE ESPAÇO, OBEDECENDO AS DIMENSÕES. Para inserir e configurar a foto, siga as orientações que se encontram no campo passo-a-passo, caso esteja oculto, clique no [2] ao lado da coluna A do cabeçalho para reexibir.
B216: 10 | C216: 5500200926 | D216: IMPLANTAÇÃO DE AJUSTES E LÓGICAS EM RELÉS EXCETO 21 E 87 E 67 | J216: OBS: | K216: 2214, NOJA POWER 4124
B218: ENQUADRAR A FOTO À ESSE ESPAÇO, OBEDECENDO AS DIMENSÕES. Para inserir e configurar a foto, siga as orientações que se encontram no campo passo-a-passo, caso esteja oculto, clique no [2] ao lado da coluna A do cabeçalho para reexibir.
B239: 11 | C239: 5500300189 | D239: MANUTENÇÃO E TESTE EM RELE DISTÂNCIA (21), DIFERENCIAL (87), DIRECIONAL (67) | J239: OBS: | K239: 2214, NOJA POWER 4124
B241: ENQUADRAR A FOTO À ESSE ESPAÇO, OBEDECENDO AS DIMENSÕES. Para inserir e configurar a foto, siga as orientações que se encontram no campo passo-a-passo, caso esteja oculto, clique no [2] ao lado da coluna A do cabeçalho para reexibir.
B262: 12 | J262: OBS:
B264: ENQUADRAR A FOTO À ESSE ESPAÇO, OBEDECENDO AS DIMENSÕES. Para inserir e configurar a foto, siga as orientações que se encontram no campo passo-a-passo, caso esteja oculto, clique no [2] ao lado da coluna A do cabeçalho para reexibir.
B285: 13 | J285: OBS:
B287: ENQUADRAR A FOTO À ESSE ESPAÇO, OBEDECENDO AS DIMENSÕES. Para inserir e configurar a foto, siga as orientações que se encontram no campo passo-a-passo, caso esteja oculto, clique no [2] ao lado da coluna A do cabeçalho para reexibir. | J287: ENQUADRAR A FOTO À ESSE ESPAÇO, OBEDECENDO AS DIMENSÕES. Para inserir e configurar a foto, siga as orientações que se encontram no campo passo-a-passo, caso esteja oculto, clique no [2] ao lado da coluna A do cabeçalho para reexibir.
B308: 14 | J308: OBS:
B310: ENQUADRAR A FOTO À ESSE ESPAÇO, OBEDECENDO AS DIMENSÕES. Para inserir e configurar a foto, siga as orientações que se encontram no campo passo-a-passo, caso esteja oculto, clique no [2] ao lado da coluna A do cabeçalho para reexibir.
B331: 15 | J331: OBS:
B333: ENQUADRAR A FOTO À ESSE ESPAÇO, OBEDECENDO AS DIMENSÕES. Para inserir e configurar a foto, siga as orientações que se encontram no campo passo-a-passo, caso esteja oculto, clique no [2] ao lado da coluna A do cabeçalho para reexibir.
B354: 16 | J354: OBS:
B356: ENQUADRAR A FOTO À ESSE ESPAÇO, OBEDECENDO AS DIMENSÕES. Para inserir e configurar a foto, siga as orientações que se encontram no campo passo-a-passo, caso esteja oculto, clique no [2] ao lado da coluna A do cabeçalho para reexibir.
B377: 17 | J377: OBS:
B379: ENQUADRAR A FOTO À ESSE ESPAÇO, OBEDECENDO AS DIMENSÕES. Para inserir e configurar a foto, siga as orientações que se encontram no campo passo-a-passo, caso esteja oculto, clique no [2] ao lado da coluna A do cabeçalho para reexibir.
...

Sheet MSRV5
A1: Chave | B1: Nº de serviço | C1: Texto breve | D1: UM básica | E1: Preço bruto | F1: Nº linha | G1: Nº de documento | H1: Item | I1: Código de eliminação
A2: =G2&H2&B2&D2 -> 4600027637105021000002UN | B2: 5021000002 | C2: INSTALAR ESTRUT PRIM CRUZETA DUPLA LM | D2: UN | E2: 3011.41 | F2: 10 | G2: 4600027637 | H2: 10
A3: =G3&H3&B3&D3 -> 4600027637105021000003UN | B3: 5021000003 | C3: INSTALAR ESTRUT PRI CRUZETA SIMPLES LM | D3: UN | E3: 2556.18 | F3: 20 | G3: 4600027637 | H3: 10
A4: =G4&H4&B4&D4 -> 4600027637105021200044un | B4: 5021200044 | C4: INST ISOLADOR ROLDANA LM | D4: un | E4: 331.09 | F4: 30 | G4: 4600027637 | H4: 10
A5: =G5&H5&B5&D5 -> 4600027637105021200045un | B5: 5021200045 | C5: RET ISOLADOR ROLDANA LM | D5: un | E5: 212.57 | F5: 40 | G5: 4600027637 | H5: 10
A6: =G6&H6&B6&D6 -> 4600027637105021200048CJ | B6: 5021200048 | C6: INST ISOLAD DISCO/ANCORAGEM LM | D6: CJ | E6: 979.41 | F6: 50 | G6: 4600027637 | H6: 10
A7: =G7&H7&B7&D7 -> 4600027637105022000079UN | B7: 5022000079 | C7: INST COND COB RD COMPACTA 150MM2 LM | D7: UN | E7: 22.19 | F7: 60 | G7: 4600027637 | H7: 10
A8: =G8&H8&B8&D8 -> 4600027637105022000250un | B8: 5022000250 | C8: INST FLY TAP/CRUZAM AEREO LM | D8: un | E8: 331.09 | F8: 70 | G8: 4600027637 | H8: 10
A9: =G9&H9&B9&D9 -> 4600027637105022000251un | B9: 5022000251 | C9: RET FLY TAP /CRUZAM AEREO LM | D9: un | E9: 212.57 | F9: 80 | G9: 4600027637 | H9: 10
A10: =G10&H10&B10&D10 -> 4600027637105022000252un | B10: 5022000252 | C10: INST ESPACAD/AFASTAD REDE PRI/SEC LM BLQ | D10: un | E10: 331.09 | F10: 90 | G10: 4600027637 | H10: 10
A11: =G11&H11&B11&D11 -> 4600027637105022000253un | B11: 5022000253 | C11: RET ESPACADOR/AFAST REDE PRI/SEC LM BLQ | D11: un | E11: 212.57 | F11: 100 | G11: 4600027637 | H11: 10
A12: =G12&H12&B12&D12 -> 4600027637105022000257un | B12: 5022000257 | C12: INST ESTRIBO OU GRAMPO LINHA VIVA RD LM | D12: un | E12: 331.09 | F12: 110 | G12: 4600027637 | H12: 10
A13: =G13&H13&B13&D13 -> 4600027637105022000258un | B13: 5022000258 | C13: RET ESTRIBO OU GRAMPO LINHA VIVA RD LM | D13: un | E13: 212.57 | F13: 120 | G13: 4600027637 | H13: 10
... A30: =G30&H30&B30&D30 -> 4600027637105045500013KM | B30: 5045500013 | C30: MOB / DESMOBILIZACAO LD DE 0 A 50KM LD | D30: KM | E30: 589.16 | F30: 290 | G30: 4600027637 | H30: 10
A31: =G31&H31&B31&D31 -> 4600027637105045500014KM | B31: 5045500014 | C31: MOB / DESMOBILIZACAO LD DE 51 A 200KM LD | D31: KM | E31: 643.72 | F31: 300 | G31: 4600027637 | H31: 10 | I31: L
A32: =G32&H32&B32&D32 -> 4600027637105045500014KM | B32: 5045500014 | C32: MOB / DESMOBILIZACAO LD DE 51 A 200KM LD | D32: KM | E32: 207.38 | F32: 310 | G32: 4600027637 | H32: 10
A33: =G33&H33&B33&D33 -> 4600027637105045500015KM | B33: 5045500015 | C33: MOB/ DESMOBILIZACAO LD ACIMA DE 600KM LD | D33: KM | E33: 207.38 | F33: 320 | G33: 4600027637 | H33: 10
A34: =G34&H34&B34&D34 -> 4600027637105045500015KM | B34: 5045500015 | C34: MOB/ DESMOBILIZACAO LD ACIMA DE 600KM LD | D34: KM | E34: 643.72 | F34: 330 | G34: 4600027637 | H34: 10
A35: =G35&H35&B35&D35 -> 4600027637105045500016KM | B35: 5045500016 | C35: MOB/ DESMOBILIZACAO LD DE 201 A 400KM LD | D35: KM | E35: 367.63 | F35: 340 | G35: 4600027637 | H35: 10
A36: =G36&H36&B36&D36 -> 4600027637105045500019CDA | B36: 5045500019 | C36: DESMOBIL 0 A 200KM EQP 5H RESIT OHM LD | D36: CDA | E36: 129.61 | F36: 350 | G36: 4600027637 | H36: 10
A37: =G37&H37&B37&D37 -> 4600027637105045500020CDA | B37: 5045500020 | C37: DESMOBIL 0 A 200KM EQP 5H SERV TEC LD | D37: CDA | E37: 164.96 | F37: 360 | G37: 4600027637 | H37: 10
A38: =G38&H38&B38&D38 -> 4600027637105045500021CDA | B38: 5045500021 | C38: DESMOBIL 201 A 400KM EQP 5H RESIT OHM LD | D38: CDA | E38: 200.33 | F38: 370 | G38: 4600027637 | H38: 10
A39: =G39&H39&B39&D39 -> 4600027637105045500022CDA | B39: 5045500022 | C39: DESMOBIL 201 A 400KM EQP 5H SERV TEC LD | D39: CDA | E39: 18.86 | F39: 380 | G39: 4600027637 | H39: 10
A40: =G40&H40&B40&D40 -> 4600027637105045500023CDA | B40: 5045500023 | C40: DESMOBIL 401 A 600KM EQP 5H RESIT OHM LD | D40: CDA | E40: 282.79 | F40: 390 | G40: 4600027637 | H40: 10
A41: =G41&H41&B41&D41 -> 4600027637105045500024CDA | B41: 5045500024 | C41: DESMOBIL 401 A 600KM EQP 5H SERV TEC LD | D41: CDA | E41: 282.79 | F41: 400 | G41: 4600027637 | H41: 10
A42: =G42&H42&B42&D42 -> 4600027637105045500030CDA | B42: 5045500030 | C42: DESMOBILIZAR 201 A 400KM EQP 5H SOND LD | D42: CDA | E42: 301.64 | F42: 410 | G42: 4600027637 | H42: 10
A43: =G43&H43&B43&D43 -> 4600027637105045500034CDA | B43: 5045500034 | C43: DESMOBILIZAR ACIMA 600KM EQP 5H SOND LD | D43: CDA | E43: 11429.61 | F43: 450 | G43: 4600027637 | H43: 10
... A907: =G907&H907&B907&D907 -> 4600027637105500400639M | B907: 5500400639 | C907: VIGA TRILHO - G-0-0-PJ-PB-105 | D907: M | E907: 9879.39 | F907: 9100 | G907: 4600027637 | H907: 10

Sheet CN43N
A1: Level | B1: Definição do projeto | C1: WBS element | D1: Name | E1: Status
A2: 2 | B2: AL-2361108GTA0 | C2: AL-2361108GTA0.A | D2: EQTL-AL>SE GTA>69KV>NOVA SE | E2: LBPA DISP // ABER
A3: 2 | B3: AL-2361108GTA0 | C3: AL-2361108GTA0.D | D3: EQTL-AL>SE SRR>69KV>AMP SE | E3: LBPA DISP // ABER
A4: 2 | B4: AL-2361208ARQ0 | C4: AL-2361208ARQ0.B | D4: EQTL-AL>SE ARQ>69KV>NOVA SE | E4: LBPA DISP // ABER
A5: 2 | B5: AL-2361208ARQ0 | C5: AL-2361208ARQ0.C | D5: EQTL-AL>SE ARD>69KV>AMP | E5: LBPA DISP // ABER
A6: 2 | B6: AL-2430208AMP0 | C6: AL-2430208AMP0.C | D6: EQTL-AL>SE SRR>AMP POT | E6: LBPA DISP // ABER
A7: 2 | B7: AL-2430208AMP0 | C7: AL-2430208AMP0.B | D7: EQTL-AL>SE CDU>AMP POT | E7: LBPA DISP // ABER
A8: 2 | B8: AL-2430608PND0 | C8: AL-2430608PND0.B | D8: EQTL-AL>SE PEN>69KV>EL | E8: LBPA DISP // ABER
A9: 2 | B9: AL-2430808CAT0 | C9: AL-2430808CAT0.B | D9: EQTL-AL>SE PCA>69KV>NOVA EL | E9: LBPA DISP // ABER
A10: 2 | B10: AL-2430808CAT0 | C10: AL-2430808CAT0.D | D10: EQTL-AL>SE JDH>13,8KV>NOVA EL | E10: LBPA DISP // ABER
A11: 2 | B11: AL-2430808CAT0 | C11: AL-2430808CAT0.E | D11: EQTL-AL>SE PIL>13,8KV>NOVA EL | E11: LBPA DISP // ABER
A12: 2 | B12: AL-2431308MOP0 | C12: AL-2431308MOP0.A | D12: EQTL-AL>SE VIS>69KV>AMP | E12: LBPA DISP // ABER
... A902: 2 | B902: RS-2562408CH30 | C902: RS-2562408CH30.C | D902: EQTL-RS>2025>SMF SE CHAR3 | E902: LBPA DISP // ABER

Sheet Portifólio
A1: EMPRESA | B1: TIPO DE OBRA | C1: DEMANDANTE | D1: PI | E1: DESCRIÇÃO PI | F1: PEP | G1: DESCRIÇÃO RESUMIDA DA OBRA | H1: SEGMENTO | I1: INSTALAÇÃO | J1: ESCOPO MODULAR | K1: COMPLEMENTO ESCOPO | L1: EXPECTATIVA ENERGIZAÇÃO DEMANDANTE | M1: EXPECTATIVA ENERGIZAÇÃO CRONOGRAMA | N1: ORÇAMENTO APROVADO 2025 | O1: ORÇAMENTO NECESSIDADE GLOBAL | P1: ORÇAMENTO NECESSIDADE < 2025 | Q1: ORÇAMENTO NECESSIDADE 2025 | R1: ORÇAMENTO NECESSIDADE > 2025 | S1: ESCOPO 2023 | T1: ESCOPO 2024 | U1: ESCOPO 2025 | V1: ESCOPO 2026 | W1: REGIONAL | X1: MUNICÍPIO | Y1: UF | Z1: LATITUDE | AA1: LONGITUDE | AB1: FASE | AC1: ESTRATÉGIA DE CONTRATAÇÃO | AD1: ID CAPEX
A2: EQTL AL | B2: AMPLIAÇÃO DE POTÊNCIA | C2: Planejamento | D2: 804.110.0302 | E2: AMPLIAÇÃO DE SUBESTAÇÕES | F2: AL-2430208AMP0.B | G2: PLANEJAMENTO - AMPLIAÇÃO DE POTÊNCIA - SE CIDADE UNIVERSITÁRIA - 2025 | H2: SE | I2: SE CIDADE UNIVERSITÁRIA | J2: 2,00 x CONEXÃO DE TRAFO 69kV c/ DJ + 1,00 x CONEXÃO DE TRAFO 13,8kV c/ DJ + 1,00 x BARRAMENTO SIMPLES 69kV + 4,00 x BARRAMENTO DUPLO OU BPT 13,8kV + 1,00 x INSTALAÇÃO DE TRANSFORMADOR DE FORÇA ATÉ 40MVA + 1,00 x BARRAMENTO SIMPLES 13,8kV + 1,00 x TRANSFORMADOR DE FORÇA 69/13,8kV 20,0/26,6MVA - DYN1 | L2: 45697.125 | M2: 45811 | N2: 5679942.4 | O2: 5889838.8 | P2: 209896.36 | Q2: 5679942.4 | R2: 0 | S2: - | T2: EXECUÇÃO | U2: FINALIZAÇÃO | V2: - | W2: LESTE - AL | Y2: AL | Z2: -9.67 | AA2: -35.74 | AB2: Mobilização | AC2: -
A3: EQTL AL | B3: AMPLIAÇÃO DE POTÊNCIA | C3: Planejamento | D3: 804.110.0302 | E3: AMPLIAÇÃO DE SUBESTAÇÕES | F3: AL-2430208AMP0.C | G3: PLANEJAMENTO - AMPLIAÇÃO DE POTÊNCIA - SE SERRARIA - 2025 | H3: SE | I3: SE SERRARIA | J3: 1,00 x TRANSFORMADOR DE FORÇA 69/13,8kV 20,0/26,6MVA - DYN1 | K3: O TRF atualmente utilizado na SE SERRARIA veio da EQTL Goiás para atender a uma demanda emergencial de carga originada da SE PINHEIRO. Inicialmente, esse equipamento seria destinado a compor a reserva técnica de manutenção, porém, foi alocado de forma emergencial para suprir essa necessidade específica. Este projeto tem como objetivo repor a reserva técnica da manutenção. | L3: 46022 | M3: 46355 | N3: 0 | O3: 2957441.6 | P3: 71426.06 | Q3: 0 | R3: 2886015.5 | S3: - | T3: - | U3: EXECUÇÃO | V3: FINALIZAÇÃO | W3: LESTE - AL | Y3: AL | Z3: -9.67 | AA3: -35.74 | AB3: Preliminar | AC3: -
A4: EQTL AL | B4: AQUISIÇÃO DE TRAFO | C4: Manutenção | D4: 804.110.0316 | E4: AQUISIÇÃO DE TRANSFORMADOR DE FORÇA | F4: AL-2431608ATF0.A | G4: MANUTENÇÃO - AQUISIÇÃO DE TRAFO - SE PAJUÇARA - 2025 | H4: SE | I4: SE PAJUÇARA | J4: 2,00 x SUBST. DE CONJUNTO TCs 13,8kV + 2,00 x TRANSFORMADOR DE FORÇA 69/13,8kV 15,0/20MVA - DYN1 + 2,00 x INSTALAÇÃO DE TRANSFORMADOR DE FORÇA ATÉ 40MVA | K4: Incluso a construção de uma parede corta-fogo entre os TRF's, além da regularização das bases e da construção de suas respectivas CSO's. | L4: 45919 | M4: 45990 | N4: 617824.32 | O4: 5253002.1 | P4: 4635177.8 | Q4: 617824.32 | R4: 0 | S4: - | T4: EXECUÇÃO | U4: FINALIZAÇÃO | V4: - | W4: LESTE - AL | Y4: AL | Z4: -9.67 | AA4: -35.74 | AB4: Mobilização | AC4: -
A5: EQTL AL | B5: BANCO DE CAPACITORES | C5: Planejamento | D5: 804.110.0301 | E5: EQUIPAMENTOS DE COMPENSAÇÃO DE REATIVOS | F5: AL-2530108BCA0.A | G5: PLANEJAMENTO - BANCO DE CAPACITORES - SE CIDADE UNIVERSITÁRIA - 2025 | H5: SE | I5: SE CIDADE UNIVERSITÁRIA | J5: 1,00 x BANCO DE CAPACITOR 3,6MVAr - 13,8kV + 1,00 x BARRAMENTO SIMPLES 13,8kV + 1,00 x CONEXÃO DE BANCO DE CAPACITOR 13,8kV c/ DJ | K5: ADIÇÃO BC 3,6 MVAR | L5: 45992 | M5: 45897 | N5: 700000 | O5: 719328.46 | P5: 19328.46 | Q5: 700000 | R5: 0 | S5: - | T5: - | U5: EXECUÇÃO | V5: - | W5: LESTE - AL | Y5: AL | Z5: -9.67 | AA5: -35.74 | AB5: Mobilização | AC5: -
A6: EQTL AL | B6: BANCO DE CAPACITORES | C6: Planejamento | D6: 804.110.0301 | E6: EQUIPAMENTOS DE COMPENSAÇÃO DE REATIVOS | F6: AL-2530108BCA0.B | G6: PLANEJAMENTO - BANCO DE CAPACITORES - SE PAJUÇARA - 2025 | H6: SE | I6: SE PAJUÇARA | J6: 1,00 x BANCO DE CAPACITOR 3,6MVAr - 13,8kV + 1,00 x BARRAMENTO SIMPLES 13,8kV + 1,00 x CONEXÃO DE BANCO DE CAPACITOR 13,8kV c/ DJ | K6: ADIÇÃO BC 3,6 MVAR | L6: 45992 | M6: 45941 | N6: 1000000 | O6: 1019328.5 | P6: 19328.46 | Q6: 1000000 | R6: 0 | S6: - | T6: - | U6: EXECUÇÃO | V6: - | W6: LESTE - AL | Y6: AL | Z6: -9.67 | AA6: -35.74 | AB6: Projeto Básico | AC6: -
A7: EQTL AL | B7: BAY | C7: Planejamento | D7: 804.110.0300 | E7: IMPLANTAÇÃO DE BAYS DE ALIMENTADORES | F7: AL-2530008BAY0.A | G7: PLANEJAMENTO - BAY - SE CORURIPE - 2025 | H7: SE | I7: SE CORURIPE | J7: 1,00 x BARRAMENTO SIMPLES 13,8kV + 1,00 x ENTRADA DE LINHA 13,8kV c/ DJ | L7: 46020.125 | M7: 45924 | N7: 590559.48 | O7: 590559.48 | P7: 0 | Q7: 590559.48 | R7: 0 | S7: - | T7: - | U7: EXECUÇÃO | V7: - | W7: OESTE - AL | Y7: AL | Z7: -10.13 | AA7: -36.18 | AB7: Projeto Básico | AC7: Pacote SE - Oeste
A8: EQTL AL | B8: BAY | C8: Planejamento | D8: 804.110.0300 | E8: IMPLANTAÇÃO DE BAYS DE ALIMENTADORES | F8: AL-2530008BAY0.B | G8: PLANEJAMENTO - BAY - SE DELMIRO GOUVEIA - 2025 | H8: SE | I8: SE DELMIRO GOUVEIA | J8: 1,00 x BARRAMENTO SIMPLES 13,8kV + 1,00 x ENTRADA DE LINHA 13,8kV c/ DJ | L8: 46020.125 | M8: 46014 | N8: 523297.12 | O8: 523297.12 | P8: 0 | Q8: 523297.12 | R8: 0 | S8: - | T8: - | U8: EXECUÇÃO | V8: - | W8: OESTE - AL | Y8: AL | Z8: -9.38 | AA8: -37.99 | AB8: Projeto Básico | AC8: Pacote SE - Oeste
A9: EQTL AL | B9: BAY | C9: Planejamento | D9: 804.110.0300 | E9: IMPLANTAÇÃO DE BAYS DE ALIMENTADORES | F9: AL-2530008BAY0.D | G9: PLANEJAMENTO - BAY - SE SÃO MIGUEL DOS CAMPOS - 2025 | H9: SE | I9: SE SÃO MIGUEL DOS CAMPOS | J9: 1,00 x BARRAMENTO SIMPLES 13,8kV + 1,00 x ENTRADA DE LINHA 13,8kV c/ DJ | L9: 46020.125 | M9: 45961 | N9: 590559.48 | O9: 590559.48 | P9: 0 | Q9: 590559.48 | R9: 0 | S9: - | T9: - | U9: EXECUÇÃO | V9: - | W9: LESTE - AL | Y9: AL | Z9: -9.77 | AA9: -36.09 | AB9: Projeto Básico | AC9: Pacote SE - Oeste
A10: EQTL AL | B10: BAY | C10: Planejamento | D10: 804.110.0300 | E10: IMPLANTAÇÃO DE BAYS DE ALIMENTADORES | F10: AL-2530008BAY0.E | G10: PLANEJAMENTO - BAY - SE SERRARIA - 2025 | H10: SE | I10: SE SERRARIA | J10: 1,00 x ENTRADA DE LINHA 13,8kV CUBÍCULO BS | L10: 46020.125 | M10: 46097 | N10: 146508.1 | O10: 590559.48 | P10: 0 | Q10: 146508.1 | R10: 444051.38 | S10: - | T10: - | U10: EXECUÇÃO | V10: - | W10: LESTE - AL | Y10: AL | Z10: -9.67 | AA10: -35.74 | AB10: Projeto Básico | AC10: Pacote SE - Oeste
A11: EQTL AL | B11: BAY | C11: Planejamento | D11: 804.110.0300 | E11: IMPLANTAÇÃO DE BAYS DE ALIMENTADORES | F11: AL-2530008BAY0.F | G11: PLANEJAMENTO - BAY - SE UNIÃO DOS PALMARES - 2025 | H11: SE | I11: SE UNIÃO DOS PALMARES | J11: 1,00 x BARRAMENTO SIMPLES 13,8kV + 1,00 x ENTRADA DE LINHA 13,8kV c/ DJ | L11: 45992.125 | M11: 46027 | N11: 1014150.2 | O11: 1114464.9 | P11: 0 | Q11: 1014150.2 | R11: 100314.71 | S11: - | T11: - | U11: EXECUÇÃO | V11: - | W11: LESTE - AL | Y11: AL | Z11: -9.16 | AA11: -36.03 | AB11: Projeto Básico | AC11: Pacote SE - Oeste
A12: EQTL AL | B12: ENTRADA DE LINHA | C12: Manutenção | D12: 804.110.0306 | E12: IMPLANTAÇÃO DE NOVAS LDs | F12: AL-2430608PND0.B | G12: MANUTENÇÃO - ENTRADA DE LINHA - SE MARITUBA - 2025 | H12: SE | I12: SE MARITUBA | J12: 1,00 x ENTRADA DE LINHA 69kV c/ DJ | L12: 46022 | M12: 45999 | N12: 855547 | O12: 855547 | P12: 0 | Q12: 855547 | R12: 0 | S12: - | T12: - | U12: EXECUÇÃO | V12: - | W12: OESTE - AL | Y12: AL | Z12: -10.28 | AA12: -36.4 | AB12: Módulo
A13: EQTL AL | B13: ENTRADA DE LINHA | C13: Manutenção | D13: 804.110.0311 | E13: Implantação de Novas LDs | F13: AL-2531108MCH0.B | G13: MANUTENÇÃO - ENTRADA DE LINHA - SE MARECHAL DEODORO - 2025 | H13: SE | I13: SE MARECHAL DEODORO | J13: 1,00 x BARRAMENTO SIMPLES 69kV + 1,00 x ENTRADA DE LINHA 69kV c/ DJ | L13: 46022.125 | M13: 45993 | N13: 865893.37 | O13: 962103.75 | P13: 0 | Q13: 865893.37 | R13: 96210.38 | S13: - | T13: - | U13: EXECUÇÃO | V13: - | W13: OESTE - AL | Y13: AL | Z13: -9.71 | AA13: -35.9 | AB13: Projeto Básico | AC13: PACOTE SE - LESTE
